<?xml version="1.0"?>
<robot xmlns:xacro="http://www.ros.org/wiki/xacro" name="inmoov" version="1.0">
  <!-- mesh_dir and use_gazebo_sim set by parent (inmoov.urdf.xacro) -->

  <joint name="Empty.001_link_joint" type="fixed">
    <origin rpy="0.00000 0.00000 0.00000" xyz="-0.00394 0.00025 -0.19163"/>
    <parent link="base_node"/>
    <child link="stand_link"/>
  </joint>
  <joint name="Empty.002_link_joint" type="continuous">
    <limit lower="0" upper="0" effort="0.00000" velocity="0.78540"/>
    <origin rpy="0.00000 0.00000 0.00000" xyz="0.00000 0.00000 8.97279"/>
    <parent link="stand_link"/>
    <child link="torso_bottom_link"/>
    <axis xyz="0.00000 0.00000 1.00000"/>
  </joint>
  <joint name="i01.head.eyeRight_link_joint" type="revolute">
    <limit lower="-0.78530" upper="0.78530" effort="0.00000" velocity="0.78540"/>
    <origin rpy="0.00000 -0.00000 0.00000" xyz="-0.00000 -0.00590 0.00000"/>
    <parent link="i01.head.eyeRight.001_link"/>
    <child link="i01.head.eyeRight_link"/>
    <axis xyz="0.99994 0.00000 0.01111"/>
  </joint>
  <joint name="i01.head.jaw_link_joint" type="revolute">
    <limit lower="0.00000" upper="0.17453" effort="0.00000" velocity="0.78540"/>
    <origin rpy="-0.00000 -0.00000 -1.57080" xyz="-0.36176 0.01121 0.32442"/>
    <parent link="i01.head.rothead_link"/>
    <child link="i01.head.jaw_link"/>
    <axis xyz="0.99994 0.00000 0.01111"/>
  </joint>
  <joint name="left_shoulder_y_link_joint" type="revolute">
    <limit lower="0.00000" upper="1.57080" effort="0.00000" velocity="0.78540"/>
    <origin rpy="0.00021 -0.00000 -0.00000" xyz="1.35472 -0.00337 2.80749"/>
    <parent link="torso_y_link"/>
    <child link="left_shoulder_y_link"/>
    <axis xyz="0.00000 -0.99994 0.01111"/>
  </joint>
  <joint name="left_shoulder_x_link_joint" type="revolute">
    <limit lower="-1.57080" upper="2.35619" effort="0.00000" velocity="0.78540"/>
    <origin rpy="-0.00000 -0.00000 -0.00000" xyz="0.11351 0.00189 -0.37504"/>
    <parent link="left_shoulder_y_link"/>
    <child link="left_shoulder_x_link"/>
    <axis xyz="-0.99994 0.00000 0.01111"/>
  </joint>
  <joint name="left_shoulder_z_link_joint" type="revolute">
    <limit lower="-1.57080" upper="1.57080" effort="0.00000" velocity="0.78540"/>
    <origin rpy="0.00000 0.00000 0.00000" xyz="0.62406 -0.00937 -0.59421"/>
    <parent link="left_shoulder_x_link"/>
    <child link="left_shoulder_z_link"/>
    <axis xyz="0.00000 0.00000 1.00000"/>
  </joint>
  <joint name="left_elbow_x_link_joint" type="revolute">
    <limit lower="0.00000" upper="1.57080" effort="0.00000" velocity="0.78540"/>
    <origin rpy="0.06567 -0.00000 -0.00000" xyz="-0.01281 0.29228 -2.11577"/>
    <parent link="left_shoulder_z_link"/>
    <child link="left_elbow_x_link"/>
    <axis xyz="-0.99994 0.00000 0.01111"/>
  </joint>
  <joint name="left_wrist_z_link_joint" type="revolute">
    <limit lower="-1.57080" upper="1.57080" effort="0.00000" velocity="0.78540"/>
    <origin rpy="-0.41605 -0.00000 0.00000" xyz="-0.08767 -0.98766 -2.53936"/>
    <parent link="left_elbow_x_link"/>
    <child link="left_wrist_z_link"/>
    <axis xyz="0.00000 0.00000 1.00000"/>
  </joint>
  <joint name="i01.leftHand.wrist.001_link_joint" type="revolute">
    <limit lower="0.00000" upper="1.57080" effort="0.00000" velocity="0.78540"/>
    <origin rpy="-0.00000 0.00000 -0.61611" xyz="-0.00000 -0.00000 -0.16925"/>
    <parent link="left_wrist_z_link"/>
    <child link="i01.leftHand.wrist.001_link"/>
    <axis xyz="-0.99994 0.00000 0.01111"/>
  </joint>
  <joint name="i01.leftHand.index_link_joint" type="revolute">
    <limit lower="0.00000" upper="1.57080" effort="0.00000" velocity="0.78540"/>
    <origin rpy="-1.56854 -0.09096 -0.00330" xyz="0.32645 -0.01145 -0.94982"/>
    <parent link="i01.leftHand.wrist.001_link"/>
    <child link="i01.leftHand.index_link"/>
    <axis xyz="-0.99994 0.00000 0.01111"/>
  </joint>
  <joint name="i01.leftHand.index2_link_joint" type="revolute">
    <limit lower="0.00000" upper="1.57080" effort="0.00000" velocity="0.78540"/>
    <origin rpy="-0.00000 0.00000 -0.00000" xyz="0.00258 0.34105 0.00685"/>
    <parent link="i01.leftHand.index_link"/>
    <child link="i01.leftHand.index2_link"/>
    <axis xyz="-0.99994 0.00000 0.01111"/>
  </joint>
  <joint name="i01.torso.midStom_link_joint" type="revolute">
    <limit lower="-2.35619" upper="2.35619" effort="0.00000" velocity="0.78540"/>
    <origin rpy="0.00000 0.06589 1.57080" xyz="-0.00213 0.05565 1.13807"/>
    <parent link="torso_bottom_link"/>
    <child link="torso_z_link"/>
    <axis xyz="0.00000 0.00000 1.00000"/>
  </joint>
  <joint name="i01.leftHand.index3_link_joint" type="revolute">
    <limit lower="0.00000" upper="1.57080" effort="0.00000" velocity="0.78540"/>
    <origin rpy="0.00000 -0.00000 -0.00000" xyz="0.00103 0.22697 0.00433"/>
    <parent link="i01.leftHand.index2_link"/>
    <child link="i01.leftHand.index3_link"/>
    <axis xyz="-0.99994 0.00000 0.01111"/>
  </joint>
  <joint name="i01.leftHand.majeure_link_joint" type="revolute">
    <limit lower="0.00000" upper="1.57080" effort="0.00000" velocity="0.78540"/>
    <origin rpy="-1.56854 0.00160 -0.00309" xyz="0.07161 -0.01170 -0.98881"/>
    <parent link="i01.leftHand.wrist.001_link"/>
    <child link="i01.leftHand.majeure_link"/>
    <axis xyz="-0.99994 0.00000 0.01111"/>
  </joint>
  <joint name="i01.leftHand.majeure2_link_joint" type="revolute">
    <limit lower="0.00000" upper="1.57080" effort="0.00000" velocity="0.78540"/>
    <origin rpy="-0.00000 -0.00000 0.00000" xyz="0.00272 0.35935 0.00722"/>
    <parent link="i01.leftHand.majeure_link"/>
    <child link="i01.leftHand.majeure2_link"/>
    <axis xyz="-0.99994 0.00000 0.01111"/>
  </joint>
  <joint name="i01.leftHand.majeure3_link_joint" type="revolute">
    <limit lower="0.00000" upper="1.57080" effort="0.00000" velocity="0.78540"/>
    <origin rpy="0.00000 -0.00000 -0.00000" xyz="0.00109 0.23915 0.00456"/>
    <parent link="i01.leftHand.majeure2_link"/>
    <child link="i01.leftHand.majeure3_link"/>
    <axis xyz="-0.99994 0.00000 0.01111"/>
  </joint>
  <joint name="i01.leftHand.pinky0_link_joint" type="revolute">
    <limit lower="0.00000" upper="1.57080" effort="0.00000" velocity="0.78540"/>
    <origin rpy="-1.56789 -0.68643 -0.00494" xyz="-0.24002 0.00108 -0.35218"/>
    <parent link="i01.leftHand.wrist.001_link"/>
    <child link="i01.leftHand.pinky0_link"/>
    <axis xyz="0.00000 -0.99994 0.01111"/>
  </joint>
  <joint name="i01.leftHand.pinky_link_joint" type="revolute">
    <limit lower="0.00000" upper="1.57080" effort="0.00000" velocity="0.78540"/>
    <origin rpy="-0.00000 0.00000 0.94526" xyz="-0.43178 0.20489 0.00726"/>
    <parent link="i01.leftHand.pinky0_link"/>
    <child link="i01.leftHand.pinky_link"/>
    <axis xyz="-0.99994 0.00000 0.01111"/>
  </joint>
  <joint name="i01.leftHand.pinky2_link_joint" type="revolute">
    <limit lower="0.00000" upper="1.57080" effort="0.00000" velocity="0.78540"/>
    <origin rpy="-0.00000 0.00000 -0.00000" xyz="0.00225 0.29796 0.00599"/>
    <parent link="i01.leftHand.pinky_link"/>
    <child link="i01.leftHand.pinky2_link"/>
    <axis xyz="-0.99994 0.00000 0.01111"/>
  </joint>
  <joint name="i01.leftHand.pinky3_link_joint" type="revolute">
    <limit lower="0.00000" upper="1.57080" effort="0.00000" velocity="0.78540"/>
    <origin rpy="-0.00000 -0.00000 -0.00000" xyz="0.00090 0.19830 0.00378"/>
    <parent link="i01.leftHand.pinky2_link"/>
    <child link="i01.leftHand.pinky3_link"/>
    <axis xyz="-0.99994 0.00000 0.01111"/>
  </joint>
  <joint name="i01.leftHand.ringfinger0_link_joint" type="revolute">
    <limit lower="0.00000" upper="1.57080" effort="0.00000" velocity="0.78540"/>
    <origin rpy="-1.56789 -0.68643 -0.00494" xyz="-0.05673 0.00101 -0.57588"/>
    <parent link="i01.leftHand.wrist.001_link"/>
    <child link="i01.leftHand.ringfinger0_link"/>
    <axis xyz="0.00000 -0.99994 0.01111"/>
  </joint>
  <joint name="i01.leftHand.ringFinger_link_joint" type="revolute">
    <limit lower="0.00000" upper="1.57080" effort="0.00000" velocity="0.78540"/>
    <origin rpy="-0.00000 0.00000 0.77485" xyz="-0.33329 0.15280 -0.00664"/>
    <parent link="i01.leftHand.ringfinger0_link"/>
    <child link="i01.leftHand.ringFinger_link"/>
    <axis xyz="-0.99994 0.00000 0.01111"/>
  </joint>
  <joint name="i01.torso.topStom_link_joint" type="revolute">
    <limit lower="-0.34907" upper="0.34907" effort="0.00000" velocity="0.78540"/>
    <origin rpy="0.00000 0.00000 -1.57080" xyz="-0.06317 0.00033 1.01916"/>
    <parent link="torso_z_link"/>
    <child link="torso_y_link"/>
    <axis xyz="0.00000 -0.99994 0.01111"/>
  </joint>
  <joint name="i01.leftHand.ringfinger2_link_joint" type="revolute">
    <limit lower="0.00000" upper="1.57080" effort="0.00000" velocity="0.78540"/>
    <origin rpy="-0.00000 -0.00000 0.00000" xyz="0.00258 0.34105 0.00685"/>
    <parent link="i01.leftHand.ringFinger_link"/>
    <child link="i01.leftHand.ringfinger2_link"/>
    <axis xyz="-0.99994 0.00000 0.01111"/>
  </joint>
  <joint name="i01.leftHand.ringfinger3_link_joint" type="revolute">
    <limit lower="0.00000" upper="1.57080" effort="0.00000" velocity="0.78540"/>
    <origin rpy="-0.00000 0.00000 -0.00000" xyz="0.00103 0.22697 0.00433"/>
    <parent link="i01.leftHand.ringfinger2_link"/>
    <child link="i01.leftHand.ringfinger3_link"/>
    <axis xyz="-0.99994 0.00000 0.01111"/>
  </joint>
  <joint name="i01.leftHand.thumb1_link_joint" type="revolute">
    <limit lower="0.00000" upper="1.57080" effort="0.00000" velocity="0.78540"/>
    <origin rpy="1.51635 -0.09893 -0.00332" xyz="0.28234 -0.00002 -0.37340"/>
    <parent link="i01.leftHand.wrist.001_link"/>
    <child link="i01.leftHand.thumb1_link"/>
    <axis xyz="0.00000 -0.99994 0.01111"/>
  </joint>
  <joint name="i01.leftHand.thumb_link_joint" type="revolute">
    <limit lower="0.00000" upper="1.57080" effort="0.00000" velocity="0.78540"/>
    <origin rpy="-0.03182 -0.32566 0.83064" xyz="0.25977 -0.13332 -0.00800"/>
    <parent link="i01.leftHand.thumb1_link"/>
    <child link="i01.leftHand.thumb_link"/>
    <axis xyz="-0.99994 0.00000 0.01111"/>
  </joint>
  <joint name="i01.leftHand.thumb3_link_joint" type="revolute">
    <limit lower="0.00000" upper="1.57080" effort="0.00000" velocity="0.78540"/>
    <origin rpy="0.00001 -0.00000 0.00000" xyz="0.01229 -0.33047 -0.00704"/>
    <parent link="i01.leftHand.thumb_link"/>
    <child link="i01.leftHand.thumb3_link"/>
    <axis xyz="-0.99994 0.00000 0.01111"/>
  </joint>
  <joint name="right_shoulder_y_link_joint" type="revolute">
    <limit lower="0.00000" upper="1.57080" effort="0.00000" velocity="0.78540"/>
    <origin rpy="0.00021 -0.00000 -0.00000" xyz="-1.34979 -0.00337 2.80749"/>
    <parent link="torso_y_link"/>
    <child link="right_shoulder_y_link"/>
    <axis xyz="0.00000 0.99994 0.01111"/>
  </joint>
  <joint name="right_shoulder_x_link_joint" type="revolute">
    <limit lower="-1.57080" upper="2.35619" effort="0.00000" velocity="0.78540"/>
    <origin rpy="-0.00000 -0.00000 -0.00000" xyz="-0.11351 0.00189 -0.37504"/>
    <parent link="right_shoulder_y_link"/>
    <child link="right_shoulder_x_link"/>
    <axis xyz="-0.99994 0.00000 0.01111"/>
  </joint>
  <joint name="right_shoulder_z_link_joint" type="revolute">
    <limit lower="-1.57080" upper="1.57080" effort="0.00000" velocity="0.78540"/>
    <origin rpy="0.00000 0.00000 0.00000" xyz="-0.62406 -0.00937 -0.59421"/>
    <parent link="right_shoulder_x_link"/>
    <child link="right_shoulder_z_link"/>
    <axis xyz="0.00000 0.00000 1.00000"/>
  </joint>
  <joint name="right_elbow" type="revolute">
    <limit lower="0.00000" upper="1.57080" effort="0.00000" velocity="0.78540"/>
    <origin rpy="0.06567 0.00000 0.00000" xyz="0.00858 0.29228 -2.11577"/>
    <parent link="right_shoulder_z_link"/>
    <child link="right_elbow_x_link"/>
    <axis xyz="-0.99994 0.00000 0.01111"/>
  </joint>
  <joint name="right_wrist_z_link_joint" type="revolute">
    <limit lower="-1.57080" upper="1.57080" effort="0.00000" velocity="0.78540"/>
    <origin rpy="-0.41605 0.00000 0.00000" xyz="0.08767 -0.98766 -2.53936"/>
    <parent link="right_elbow_x_link"/>
    <child link="right_wrist_z_link"/>
    <axis xyz="0.00000 0.00000 1.00000"/>
  </joint>
  <joint name="i01.head.neck.001_link_joint" type="revolute">
    <limit lower="-0.34907" upper="0.34907" effort="0.00000" velocity="0.78540"/>
    <origin rpy="0.06589 -0.00000 -0.00000" xyz="0.00390 0.29817 4.29073"/>
    <parent link="torso_y_link"/>
    <child link="i01.head.neck.001_link"/>
    <axis xyz="0.99994 0.00000 0.01111"/>
  </joint>
  <joint name="i01.rightHand.wrist.001_link_joint" type="revolute">
    <limit lower="0.00000" upper="1.57080" effort="0.00000" velocity="0.78540"/>
    <origin rpy="0.00000 0.00000 0.63517" xyz="-0.00000 -0.00000 -0.16508"/>
    <parent link="right_wrist_z_link"/>
    <child link="i01.rightHand.wrist.001_link"/>
    <axis xyz="-0.99994 0.00000 0.01111"/>
  </joint>
  <joint name="i01.rightHand.index_link_joint" type="revolute">
    <limit lower="0.00000" upper="1.57080" effort="0.00000" velocity="0.78540"/>
    <origin rpy="1.57305 0.09096 -0.01576" xyz="-0.32320 -0.00773 -0.95398"/>
    <parent link="i01.rightHand.wrist.001_link"/>
    <child link="i01.rightHand.index_link"/>
    <axis xyz="-0.99994 0.00000 0.01111"/>
  </joint>
  <joint name="i01.rightHand.index2_link_joint" type="revolute">
    <limit lower="0.00000" upper="1.57080" effort="0.00000" velocity="0.78540"/>
    <origin rpy="0.00000 -0.00000 0.00000" xyz="-0.00258 -0.34105 -0.00685"/>
    <parent link="i01.rightHand.index_link"/>
    <child link="i01.rightHand.index2_link"/>
    <axis xyz="-0.99994 0.00000 0.01111"/>
  </joint>
  <joint name="i01.rightHand.index3_link_joint" type="revolute">
    <limit lower="0.00000" upper="1.57080" effort="0.00000" velocity="0.78540"/>
    <origin rpy="0.00000 0.00000 -0.00000" xyz="-0.00103 -0.22697 -0.00432"/>
    <parent link="i01.rightHand.index2_link"/>
    <child link="i01.rightHand.index3_link"/>
    <axis xyz="-0.99994 0.00000 0.01111"/>
  </joint>
  <joint name="i01.rightHand.majeure_link_joint" type="revolute">
    <limit lower="0.00000" upper="1.57080" effort="0.00000" velocity="0.78540"/>
    <origin rpy="1.57305 -0.00160 -0.01597" xyz="-0.06841 -0.01284 -0.99297"/>
    <parent link="i01.rightHand.wrist.001_link"/>
    <child link="i01.rightHand.majeure_link"/>
    <axis xyz="-0.99994 0.00000 0.01111"/>
  </joint>
  <joint name="i01.rightHand.majeure2_link_joint" type="revolute">
    <limit lower="0.00000" upper="1.57080" effort="0.00000" velocity="0.78540"/>
    <origin rpy="-0.00000 -0.00000 -0.00000" xyz="-0.00272 -0.35935 -0.00722"/>
    <parent link="i01.rightHand.majeure_link"/>
    <child link="i01.rightHand.majeure2_link"/>
    <axis xyz="-0.99994 0.00000 0.01111"/>
  </joint>
  <joint name="i01.rightHand.majeure3_link_joint" type="revolute">
    <limit lower="0.00000" upper="1.57080" effort="0.00000" velocity="0.78540"/>
    <origin rpy="0.00000 -0.00000 0.00000" xyz="-0.00109 -0.23915 -0.00456"/>
    <parent link="i01.rightHand.majeure2_link"/>
    <child link="i01.rightHand.majeure3_link"/>
    <axis xyz="-0.99994 0.00000 0.01111"/>
  </joint>
  <joint name="i01.rightHand.pinky0_link_joint" type="revolute">
    <limit lower="0.00000" upper="1.57080" effort="0.00000" velocity="0.78540"/>
    <origin rpy="1.57370 0.68643 -0.01412" xyz="0.24340 -0.00601 -0.35634"/>
    <parent link="i01.rightHand.wrist.001_link"/>
    <child link="i01.rightHand.pinky0_link"/>
    <axis xyz="0.00000 -0.99994 0.01111"/>
  </joint>
  <joint name="i01.rightHand.pinky_link_joint" type="revolute">
    <limit lower="0.00000" upper="1.57080" effort="0.00000" velocity="0.78540"/>
    <origin rpy="-0.00000 -0.00000 0.94526" xyz="0.43178 -0.20489 -0.00726"/>
    <parent link="i01.rightHand.pinky0_link"/>
    <child link="i01.rightHand.pinky_link"/>
    <axis xyz="-0.99994 0.00000 0.01111"/>
  </joint>
  <joint name="i01.rightHand.pinky2_link_joint" type="revolute">
    <limit lower="0.00000" upper="1.57080" effort="0.00000" velocity="0.78540"/>
    <origin rpy="0.00000 0.00000 -0.00000" xyz="-0.00225 -0.29796 -0.00598"/>
    <parent link="i01.rightHand.pinky_link"/>
    <child link="i01.rightHand.pinky2_link"/>
    <axis xyz="-0.99994 0.00000 0.01111"/>
  </joint>
  <joint name="i01.head.rollNeck_link_joint" type="revolute">
    <limit lower="-0.34907" upper="0.34907" effort="0.00000" velocity="0.78540"/>
    <origin rpy="-0.00000 0.00000 -0.00000" xyz="0.00000 -0.00000 0.00435"/>
    <parent link="i01.head.neck.001_link"/>
    <child link="neck_link"/>
    <axis xyz="0.00000 0.99994 0.01111"/>
  </joint>
  <joint name="i01.rightHand.pinky3_link_joint" type="revolute">
    <limit lower="0.00000" upper="1.57080" effort="0.00000" velocity="0.78540"/>
    <origin rpy="0.00000 0.00000 0.00000" xyz="-0.00090 -0.19830 -0.00378"/>
    <parent link="i01.rightHand.pinky2_link"/>
    <child link="i01.rightHand.pinky3_link"/>
    <axis xyz="-0.99994 0.00000 0.01111"/>
  </joint>
  <joint name="i01.rightHand.ringfinger0_link_joint" type="revolute">
    <limit lower="0.00000" upper="1.57080" effort="0.00000" velocity="0.78540"/>
    <origin rpy="1.57370 0.68643 -0.01412" xyz="0.06015 -0.00258 -0.58004"/>
    <parent link="i01.rightHand.wrist.001_link"/>
    <child link="i01.rightHand.ringfinger0_link"/>
    <axis xyz="0.00000 -0.99994 0.01111"/>
  </joint>
  <joint name="i01.rightHand.ringFinger_link_joint" type="revolute">
    <limit lower="0.00000" upper="1.57080" effort="0.00000" velocity="0.78540"/>
    <origin rpy="-0.00000 -0.00000 0.77485" xyz="0.33328 -0.15280 0.00664"/>
    <parent link="i01.rightHand.ringfinger0_link"/>
    <child link="i01.rightHand.ringFinger_link"/>
    <axis xyz="-0.99994 0.00000 0.01111"/>
  </joint>
  <joint name="i01.rightHand.ringfinger2_link_joint" type="revolute">
    <limit lower="0.00000" upper="1.57080" effort="0.00000" velocity="0.78540"/>
    <origin rpy="-0.00000 -0.00000 0.00000" xyz="-0.00258 -0.34105 -0.00685"/>
    <parent link="i01.rightHand.ringFinger_link"/>
    <child link="i01.rightHand.ringfinger2_link"/>
    <axis xyz="-0.99994 0.00000 0.01111"/>
  </joint>
  <joint name="i01.rightHand.ringfinger3_link_joint" type="revolute">
    <limit lower="0.00000" upper="1.57080" effort="0.00000" velocity="0.78540"/>
    <origin rpy="-0.00000 0.00000 -0.00000" xyz="-0.00103 -0.22697 -0.00432"/>
    <parent link="i01.rightHand.ringfinger2_link"/>
    <child link="i01.rightHand.ringfinger3_link"/>
    <axis xyz="-0.99994 0.00000 0.01111"/>
  </joint>
  <joint name="i01.rightHand.thumb1_link_joint" type="revolute">
    <limit lower="0.00000" upper="1.57080" effort="0.00000" velocity="0.78540"/>
    <origin rpy="-1.62525 0.09893 -0.01574" xyz="-0.27888 0.00285 -0.37757"/>
    <parent link="i01.rightHand.wrist.001_link"/>
    <child link="i01.rightHand.thumb1_link"/>
    <axis xyz="0.00000 -0.99994 0.01111"/>
  </joint>
  <joint name="i01.rightHand.thumb_link_joint" type="revolute">
    <limit lower="0.00000" upper="1.57080" effort="0.00000" velocity="0.78540"/>
    <origin rpy="-0.03182 -0.32566 0.83064" xyz="-0.25977 0.13332 0.00800"/>
    <parent link="i01.rightHand.thumb1_link"/>
    <child link="i01.rightHand.thumb_link"/>
    <axis xyz="-0.99994 0.00000 0.01111"/>
  </joint>
  <joint name="i01.rightHand.thumb3_link_joint" type="revolute">
    <limit lower="0.00000" upper="1.57080" effort="0.00000" velocity="0.78540"/>
    <origin rpy="0.00001 -0.00000 0.00000" xyz="-0.01229 0.33047 0.00704"/>
    <parent link="i01.rightHand.thumb_link"/>
    <child link="i01.rightHand.thumb3_link"/>
    <axis xyz="-0.99994 0.00000 0.01111"/>
  </joint>
  <joint name="i01.head.rothead_link_joint" type="revolute">
    <limit lower="-0.52360" upper="0.52360" effort="0.00000" velocity="0.78540"/>
    <origin rpy="0.00000 -0.00000 1.57080" xyz="0.00246 0.01503 0.24911"/>
    <parent link="neck_link"/>
    <child link="i01.head.rothead_link"/>
    <axis xyz="0.00000 0.00000 1.00000"/>
  </joint>
  <joint name="i01.head.eyeLeft.001_link_joint" type="revolute">
    <limit lower="-0.34907" upper="0.34907" effort="0.00000" velocity="0.78540"/>
    <origin rpy="0.00000 0.00000 -1.57080" xyz="-1.08601 -0.29198 0.37576"/>
    <parent link="i01.head.rothead_link"/>
    <child link="i01.head.eyeLeft.001_link"/>
    <axis xyz="0.00000 0.00000 1.00000"/>
  </joint>
  <joint name="i01.head.eyeLeft_link_joint" type="revolute">
    <limit lower="-0.78530" upper="0.78530" effort="0.00000" velocity="0.78540"/>
    <origin rpy="0.00000 -0.00000 0.00000" xyz="0.00000 -0.00590 0.00000"/>
    <parent link="i01.head.eyeLeft.001_link"/>
    <child link="i01.head.eyeLeft_link"/>
    <axis xyz="0.99994 0.00000 0.01111"/>
  </joint>
  <joint name="i01.head.eyeRight.001_link_joint" type="revolute">
    <limit lower="-0.34907" upper="0.34907" effort="0.00000" velocity="0.78540"/>
    <origin rpy="-0.00000 -0.00000 -1.57080" xyz="-1.09644 0.29850 0.37576"/>
    <parent link="i01.head.rothead_link"/>
    <child link="i01.head.eyeRight.001_link"/>
    <axis xyz="0.00000 0.00000 1.00000"/>
  </joint>
  <link name="base_node">
    <visual name="stand">
      <material name="Gazebo/Grey"/>
      <origin rpy="3.14159 -0.00000 3.14159" xyz="-0.00394 -0.00730 9.35280"/>
      <geometry>
        <mesh filename="${mesh_dir}/stand.dae" scale="1.00000 1.00000 1.00000"/>
      </geometry>
    </visual>
    <!-- Minimal collision and inertial so sdformat/urdf2sdf includes this root link in Gazebo -->
    <collision name="base_node_collision">
      <geometry><box size="0.01 0.01 0.01"/></geometry>
    </collision>
    <inertial>
      <xacro:if value="${use_gazebo_sim}">
        <mass value="10000"/>
        <inertia ixx="100" ixy="0" ixz="0" iyy="100" iyz="0" izz="100"/>
      </xacro:if>
      <xacro:unless value="${use_gazebo_sim}">
        <mass value="0.001"/>
        <inertia ixx="1e-6" ixy="0" ixz="0" iyy="1e-6" iyz="0" izz="1e-6"/>
      </xacro:unless>
    </inertial>
  </link>
  <link name="stand_link">
    <!-- Minimal geometry so urdf2sdf does not drop this link in Gazebo -->
    <collision name="stand_link_collision">
      <geometry><box size="0.01 0.01 0.01"/></geometry>
    </collision>
    <inertial>
      <xacro:if value="${use_gazebo_sim}">
        <mass value="10000"/>
        <inertia ixx="100" ixy="0" ixz="0" iyy="100" iyz="0" izz="100"/>
      </xacro:if>
      <xacro:unless value="${use_gazebo_sim}">
        <mass value="0.001"/>
        <inertia ixx="1e-6" ixy="0" ixz="0" iyy="1e-6" iyz="0" izz="1e-6"/>
      </xacro:unless>
    </inertial>
  </link>
  <link name="i01.head.eyeRight.001_link">
    <inertial><mass value="0.001"/><inertia ixx="1e-6" ixy="0" ixz="0" iyy="1e-6" iyz="0" izz="1e-6"/></inertial>
  </link>
  <link name="i01.head.eyeRight_link">
    <visual name="i01.head.eyeRight.full">
      <material name="Material.038"/>
      <origin rpy="-0.00000 0.00000 0.00000" xyz="0.29460 0.89123 -16.02297"/>
      <geometry>
        <mesh filename="${mesh_dir}/Texture.012.dae" scale="1.00000 1.00000 1.00000"/>
      </geometry>
    </visual>
    <inertial><mass value="0.001"/><inertia ixx="1e-6" ixy="0" ixz="0" iyy="1e-6" iyz="0" izz="1e-6"/></inertial>
  </link>
  <link name="i01.head.jaw_link">
    <visual name="i01.head.mouth">
      <material name="Material.046"/>
      <origin rpy="0.00000 0.00000 -0.00000" xyz="0.00732 0.15065 -15.97164"/>
      <geometry>
        <mesh filename="${mesh_dir}/Texture.014.dae" scale="1.00000 1.00000 1.00000"/>
      </geometry>
    </visual>
    <visual name="i01.head.mouth.001">
      <material name="Material.046"/>
      <origin rpy="0.00000 0.00000 -0.00000" xyz="0.00732 0.15065 -15.97164"/>
      <geometry>
        <mesh filename="${mesh_dir}/Texture.086.dae" scale="1.00000 1.00000 1.00000"/>
      </geometry>
    </visual>
    <visual name="i01.head.mouth.002">
      <material name="Material.046"/>
      <origin rpy="0.00000 0.00000 -0.00000" xyz="0.00732 0.15065 -15.97164"/>
      <geometry>
        <mesh filename="${mesh_dir}/Texture.087.dae" scale="1.00000 1.00000 1.00000"/>
      </geometry>
    </visual>
    <inertial><mass value="0.001"/><inertia ixx="1e-6" ixy="0" ixz="0" iyy="1e-6" iyz="0" izz="1e-6"/></inertial>
  </link>
  <link name="left_shoulder_y_link">
    <visual name="i01.leftArm.omoplate.full">
      <material name="Material.254"/>
      <origin rpy="0.06568 0.00000 0.00000" xyz="-1.35226 1.11649 -13.89027"/>
      <geometry>
        <mesh filename="${mesh_dir}/Texture.004.dae" scale="1.00000 1.00000 1.00000"/>
      </geometry>
    </visual>
    <visual name="i01.leftArm.omoplate.full.001">
      <material name="Material.254"/>
      <origin rpy="0.06568 0.00000 0.00000" xyz="-1.35226 1.11649 -13.89027"/>
      <geometry>
        <mesh filename="${mesh_dir}/Texture.248.dae" scale="1.00000 1.00000 1.00000"/>
      </geometry>
    </visual>
    <visual name="i01.leftArm.omoplate.full.002">
      <material name="Material.254"/>
      <origin rpy="0.06568 0.00000 0.00000" xyz="-1.35226 1.11649 -13.89027"/>
      <geometry>
        <mesh filename="${mesh_dir}/Texture.249.dae" scale="1.00000 1.00000 1.00000"/>
      </geometry>
    </visual>
    <visual name="i01.leftArm.omoplate.full.003">
      <material name="Material.254"/>
      <origin rpy="0.06568 0.00000 0.00000" xyz="-1.35226 1.11649 -13.89027"/>
      <geometry>
        <mesh filename="${mesh_dir}/Texture.250.dae" scale="1.00000 1.00000 1.00000"/>
      </geometry>
    </visual>
    <visual name="i01.leftArm.omoplate.full.004">
      <material name="Material.254"/>
      <origin rpy="0.06568 0.00000 0.00000" xyz="-1.35226 1.11649 -13.89027"/>
      <geometry>
        <mesh filename="${mesh_dir}/Texture.251.dae" scale="1.00000 1.00000 1.00000"/>
      </geometry>
    </visual>
    <visual name="i01.leftArm.omoplate.full.005">
      <material name="Material.254"/>
      <origin rpy="0.06568 0.00000 0.00000" xyz="-1.35226 1.11649 -13.89027"/>
      <geometry>
        <mesh filename="${mesh_dir}/Texture.252.dae" scale="1.00000 1.00000 1.00000"/>
      </geometry>
    </visual>
    <visual name="i01.leftArm.omoplate.full.006">
      <material name="Material.254"/>
      <origin rpy="0.06568 0.00000 0.00000" xyz="-1.35226 1.11649 -13.89027"/>
      <geometry>
        <mesh filename="${mesh_dir}/Texture.253.dae" scale="1.00000 1.00000 1.00000"/>
      </geometry>
    </visual>
    <inertial><mass value="0.001"/><inertia ixx="1e-6" ixy="0" ixz="0" iyy="1e-6" iyz="0" izz="1e-6"/></inertial>
  </link>
  <link name="left_shoulder_x_link">
    <visual name="i01..leftArm.shoulder.full">
      <material name="Material.239"/>
      <origin rpy="0.06568 0.00000 0.00000" xyz="-1.46578 1.11459 -13.51522"/>
      <geometry>
        <mesh filename="${mesh_dir}/Texture.003.dae" scale="1.00000 1.00000 1.00000"/>
      </geometry>
    </visual>
    <visual name="i01..leftArm.shoulder.full.001">
      <material name="Material.390"/>
      <origin rpy="0.06568 0.00000 0.00000" xyz="-1.46578 1.11459 -13.51522"/>
      <geometry>
        <mesh filename="${mesh_dir}/Texture.254.dae" scale="1.00000 1.00000 1.00000"/>
      </geometry>
    </visual>
    <visual name="i01..leftArm.shoulder.full.002">
      <material name="Material.390"/>
      <origin rpy="0.06568 0.00000 0.00000" xyz="-1.46578 1.11459 -13.51522"/>
      <geometry>
        <mesh filename="${mesh_dir}/Texture.255.dae" scale="1.00000 1.00000 1.00000"/>
      </geometry>
    </visual>
    <visual name="i01..leftArm.shoulder.full.003">
      <material name="Material.390"/>
      <origin rpy="0.06568 0.00000 0.00000" xyz="-1.46578 1.11459 -13.51522"/>
      <geometry>
        <mesh filename="${mesh_dir}/Texture.256.dae" scale="1.00000 1.00000 1.00000"/>
      </geometry>
    </visual>
    <visual name="i01..leftArm.shoulder.full.004">
      <material name="Material.390"/>
      <origin rpy="0.06568 0.00000 0.00000" xyz="-1.46578 1.11459 -13.51522"/>
      <geometry>
        <mesh filename="${mesh_dir}/Texture.257.dae" scale="1.00000 1.00000 1.00000"/>
      </geometry>
    </visual>
    <visual name="i01..leftArm.shoulder.full.005">
      <material name="Material.390"/>
      <origin rpy="0.06568 0.00000 0.00000" xyz="-1.46578 1.11459 -13.51522"/>
      <geometry>
        <mesh filename="${mesh_dir}/Texture.258.dae" scale="1.00000 1.00000 1.00000"/>
      </geometry>
    </visual>
    <visual name="i01..leftArm.shoulder.full.006">
      <material name="Material.390"/>
      <origin rpy="0.06568 0.00000 0.00000" xyz="-1.46578 1.11459 -13.51522"/>
      <geometry>
        <mesh filename="${mesh_dir}/Texture.259.dae" scale="1.00000 1.00000 1.00000"/>
      </geometry>
    </visual>
    <visual name="i01..leftArm.shoulder.full.007">
      <material name="Material.390"/>
      <origin rpy="0.06568 0.00000 0.00000" xyz="-1.46578 1.11459 -13.51522"/>
      <geometry>
        <mesh filename="${mesh_dir}/Texture.260.dae" scale="1.00000 1.00000 1.00000"/>
      </geometry>
    </visual>
    <visual name="i01..leftArm.shoulder.full.008">
      <material name="Material.390"/>
      <origin rpy="0.06568 0.00000 0.00000" xyz="-1.46578 1.11459 -13.51522"/>
      <geometry>
        <mesh filename="${mesh_dir}/Texture.261.dae" scale="1.00000 1.00000 1.00000"/>
      </geometry>
    </visual>
    <visual name="i01..leftArm.shoulder.full.009">
      <material name="Material.390"/>
      <origin rpy="0.06568 0.00000 0.00000" xyz="-1.46578 1.11459 -13.51522"/>
      <geometry>
        <mesh filename="${mesh_dir}/Texture.262.dae" scale="1.00000 1.00000 1.00000"/>
      </geometry>
    </visual>
    <visual name="i01..leftArm.shoulder.full.010">
      <material name="Material.390"/>
      <origin rpy="0.06568 0.00000 0.00000" xyz="-1.46578 1.11459 -13.51522"/>
      <geometry>
        <mesh filename="${mesh_dir}/Texture.263.dae" scale="1.00000 1.00000 1.00000"/>
      </geometry>
    </visual>
    <visual name="i01..leftArm.shoulder.full.011">
      <material name="Material.390"/>
      <origin rpy="0.06568 0.00000 0.00000" xyz="-1.46578 1.11459 -13.51522"/>
      <geometry>
        <mesh filename="${mesh_dir}/Texture.264.dae" scale="1.00000 1.00000 1.00000"/>
      </geometry>
    </visual>
    <visual name="i01..leftArm.shoulder.full.014">
      <material name="Material.390"/>
      <origin rpy="0.06568 0.00000 0.00000" xyz="-1.46578 1.11459 -13.51522"/>
      <geometry>
        <mesh filename="${mesh_dir}/Texture.267.dae" scale="1.00000 1.00000 1.00000"/>
      </geometry>
    </visual>
    <visual name="i01..leftArm.shoulder.full.015">
      <material name="Material.390"/>
      <origin rpy="0.06568 0.00000 0.00000" xyz="-1.46578 1.11459 -13.51522"/>
      <geometry>
        <mesh filename="${mesh_dir}/Texture.268.dae" scale="1.00000 1.00000 1.00000"/>
      </geometry>
    </visual>
    <visual name="i01..leftArm.shoulder.full.016">
      <material name="Material.390"/>
      <origin rpy="0.06568 0.00000 0.00000" xyz="-1.46578 1.11459 -13.51522"/>
      <geometry>
        <mesh filename="${mesh_dir}/Texture.269.dae" scale="1.00000 1.00000 1.00000"/>
      </geometry>
    </visual>
    <visual name="i01..leftArm.shoulder.full.017">
      <material name="Material.390"/>
      <origin rpy="0.06568 0.00000 0.00000" xyz="-1.46578 1.11459 -13.51522"/>
      <geometry>
        <mesh filename="${mesh_dir}/Texture.270.dae" scale="1.00000 1.00000 1.00000"/>
      </geometry>
    </visual>
    <inertial><mass value="0.001"/><inertia ixx="1e-6" ixy="0" ixz="0" iyy="1e-6" iyz="0" izz="1e-6"/></inertial>
  </link>
  <link name="left_shoulder_z_link">
    <visual name="i01.leftArm.rotate.full">
      <material name="[0131_Silver].001"/>
      <origin rpy="-0.00792 -0.00000 -0.00000" xyz="-2.08983 1.12391 -12.92101"/>
      <geometry>
        <mesh filename="${mesh_dir}/G-__564753.dae" scale="1.00000 1.00000 1.00000"/>
      </geometry>
    </visual>
    <visual name="i01.leftArm.rotate.full.001">
      <material name="[0131_Silver].001"/>
      <origin rpy="-0.00792 -0.00000 -0.00000" xyz="-2.08983 1.12391 -12.92101"/>
      <geometry>
        <mesh filename="${mesh_dir}/G-__564753.001.dae" scale="1.00000 1.00000 1.00000"/>
      </geometry>
    </visual>
    <visual name="i01.leftArm.rotate.full.002">
      <material name="[0131_Silver].001"/>
      <origin rpy="-0.00792 -0.00000 -0.00000" xyz="-2.08983 1.12391 -12.92101"/>
      <geometry>
        <mesh filename="${mesh_dir}/G-__564753.002.dae" scale="1.00000 1.00000 1.00000"/>
      </geometry>
    </visual>
    <visual name="i01.leftArm.rotate.full.003">
      <material name="[0131_Silver].001"/>
      <origin rpy="-0.00792 -0.00000 -0.00000" xyz="-2.08983 1.12391 -12.92101"/>
      <geometry>
        <mesh filename="${mesh_dir}/G-__564753.003.dae" scale="1.00000 1.00000 1.00000"/>
      </geometry>
    </visual>
    <visual name="i01.leftArm.rotate.full.004">
      <material name="[0131_Silver].001"/>
      <origin rpy="-0.00792 -0.00000 -0.00000" xyz="-2.08983 1.12391 -12.92101"/>
      <geometry>
        <mesh filename="${mesh_dir}/G-__564753.004.dae" scale="1.00000 1.00000 1.00000"/>
      </geometry>
    </visual>
    <visual name="i01.leftArm.rotate.full.005">
      <material name="[0131_Silver].001"/>
      <origin rpy="-0.00792 -0.00000 -0.00000" xyz="-2.08983 1.12391 -12.92101"/>
      <geometry>
        <mesh filename="${mesh_dir}/G-__564753.005.dae" scale="1.00000 1.00000 1.00000"/>
      </geometry>
    </visual>
    <visual name="i01.leftArm.rotate.full.006">
      <material name="[0131_Silver].001"/>
      <origin rpy="-0.00792 -0.00000 -0.00000" xyz="-2.08983 1.12391 -12.92101"/>
      <geometry>
        <mesh filename="${mesh_dir}/G-__564753.006.dae" scale="1.00000 1.00000 1.00000"/>
      </geometry>
    </visual>
    <visual name="i01.leftArm.rotate.full.007">
      <material name="[0131_Silver].001"/>
      <origin rpy="-0.00792 -0.00000 -0.00000" xyz="-2.08983 1.12391 -12.92101"/>
      <geometry>
        <mesh filename="${mesh_dir}/G-__564753.007.dae" scale="1.00000 1.00000 1.00000"/>
      </geometry>
    </visual>
    <visual name="i01.leftArm.rotate.full.008">
      <material name="[0131_Silver].001"/>
      <origin rpy="-0.00792 -0.00000 -0.00000" xyz="-2.08983 1.12391 -12.92101"/>
      <geometry>
        <mesh filename="${mesh_dir}/G-__564753.008.dae" scale="1.00000 1.00000 1.00000"/>
      </geometry>
    </visual>
    <visual name="i01.leftArm.rotate.full.009">
      <material name="[0131_Silver].001"/>
      <origin rpy="-0.00792 -0.00000 -0.00000" xyz="-2.08983 1.12391 -12.92101"/>
      <geometry>
        <mesh filename="${mesh_dir}/G-__564753.009.dae" scale="1.00000 1.00000 1.00000"/>
      </geometry>
    </visual>
    <visual name="i01.leftArm.rotate.full.010">
      <material name="[0131_Silver].001"/>
      <origin rpy="-0.00792 -0.00000 -0.00000" xyz="-2.08983 1.12391 -12.92101"/>
      <geometry>
        <mesh filename="${mesh_dir}/G-__564753.010.dae" scale="1.00000 1.00000 1.00000"/>
      </geometry>
    </visual>
    <visual name="i01.leftArm.rotate.full.011">
      <material name="[0131_Silver].001"/>
      <origin rpy="-0.00792 -0.00000 -0.00000" xyz="-2.08983 1.12391 -12.92101"/>
      <geometry>
        <mesh filename="${mesh_dir}/G-__564753.011.dae" scale="1.00000 1.00000 1.00000"/>
      </geometry>
    </visual>
    <visual name="i01.leftArm.rotate.full.012">
      <material name="[0131_Silver].001"/>
      <origin rpy="-0.00792 -0.00000 -0.00000" xyz="-2.08983 1.12391 -12.92101"/>
      <geometry>
        <mesh filename="${mesh_dir}/G-__564753.012.dae" scale="1.00000 1.00000 1.00000"/>
      </geometry>
    </visual>
    <visual name="i01.leftArm.rotate.full.013">
      <material name="[0131_Silver].001"/>
      <origin rpy="-0.00792 -0.00000 -0.00000" xyz="-2.08983 1.12391 -12.92101"/>
      <geometry>
        <mesh filename="${mesh_dir}/G-__564753.013.dae" scale="1.00000 1.00000 1.00000"/>
      </geometry>
    </visual>
    <visual name="i01.leftArm.rotate.full.014">
      <material name="[0131_Silver].001"/>
      <origin rpy="-0.00792 -0.00000 -0.00000" xyz="-2.08983 1.12391 -12.92101"/>
      <geometry>
        <mesh filename="${mesh_dir}/G-__564753.014.dae" scale="1.00000 1.00000 1.00000"/>
      </geometry>
    </visual>
    <visual name="i01.leftArm.rotate.full.015">
      <material name="[0131_Silver].001"/>
      <origin rpy="-0.00792 -0.00000 -0.00000" xyz="-2.08983 1.12391 -12.92101"/>
      <geometry>
        <mesh filename="${mesh_dir}/G-__564753.015.dae" scale="1.00000 1.00000 1.00000"/>
      </geometry>
    </visual>
    <visual name="i01.leftArm.rotate.full.016">
      <material name="[0131_Silver].001"/>
      <origin rpy="-0.00792 -0.00000 -0.00000" xyz="-2.08983 1.12391 -12.92101"/>
      <geometry>
        <mesh filename="${mesh_dir}/G-__564753.016.dae" scale="1.00000 1.00000 1.00000"/>
      </geometry>
    </visual>
    <visual name="i01.leftArm.rotate.full.017">
      <material name="[0131_Silver].001"/>
      <origin rpy="-0.00792 -0.00000 -0.00000" xyz="-2.08983 1.12391 -12.92101"/>
      <geometry>
        <mesh filename="${mesh_dir}/G-__564753.017.dae" scale="1.00000 1.00000 1.00000"/>
      </geometry>
    </visual>
    <visual name="i01.leftArm.rotate.full.018">
      <material name="[0131_Silver].001"/>
      <origin rpy="-0.00792 -0.00000 -0.00000" xyz="-2.08983 1.12391 -12.92101"/>
      <geometry>
        <mesh filename="${mesh_dir}/G-__564753.018.dae" scale="1.00000 1.00000 1.00000"/>
      </geometry>
    </visual>
    <visual name="i01.leftArm.rotate.full.019">
      <material name="[0131_Silver].001"/>
      <origin rpy="-0.00792 -0.00000 -0.00000" xyz="-2.08983 1.12391 -12.92101"/>
      <geometry>
        <mesh filename="${mesh_dir}/G-__564753.019.dae" scale="1.00000 1.00000 1.00000"/>
      </geometry>
    </visual>
    <visual name="i01.leftArm.rotate.full.020">
      <material name="[0131_Silver].001"/>
      <origin rpy="-0.00792 -0.00000 -0.00000" xyz="-2.08983 1.12391 -12.92101"/>
      <geometry>
        <mesh filename="${mesh_dir}/G-__564753.020.dae" scale="1.00000 1.00000 1.00000"/>
      </geometry>
    </visual>
    <inertial><mass value="0.001"/><inertia ixx="1e-6" ixy="0" ixz="0" iyy="1e-6" iyz="0" izz="1e-6"/></inertial>
  </link>
  <link name="left_elbow_x_link">
    <visual name="i01.left.bicep.full">
      <material name="Material.022"/>
      <origin rpy="-0.00000 0.00000 0.00000" xyz="-2.07702 0.12073 -10.83652"/>
      <geometry>
        <mesh filename="${mesh_dir}/Texture.007.dae" scale="1.00000 1.00000 1.00000"/>
      </geometry>
    </visual>
    <visual name="i01.left.bicep.full.001">
      <material name="Material.022"/>
      <origin rpy="-0.00000 0.00000 0.00000" xyz="-2.07702 0.12073 -10.83652"/>
      <geometry>
        <mesh filename="${mesh_dir}/Texture.236.dae" scale="1.00000 1.00000 1.00000"/>
      </geometry>
    </visual>
    <visual name="i01.left.bicep.full.002">
      <material name="Material.022"/>
      <origin rpy="-0.00000 0.00000 0.00000" xyz="-2.07702 0.12073 -10.83652"/>
      <geometry>
        <mesh filename="${mesh_dir}/Texture.237.dae" scale="1.00000 1.00000 1.00000"/>
      </geometry>
    </visual>
    <visual name="i01.left.bicep.full.003">
      <material name="Material.022"/>
      <origin rpy="-0.00000 0.00000 0.00000" xyz="-2.07702 0.12073 -10.83652"/>
      <geometry>
        <mesh filename="${mesh_dir}/Texture.238.dae" scale="1.00000 1.00000 1.00000"/>
      </geometry>
    </visual>
    <visual name="i01.left.bicep.full.004">
      <material name="Material.022"/>
      <origin rpy="-0.00000 0.00000 0.00000" xyz="-2.07702 0.12073 -10.83652"/>
      <geometry>
        <mesh filename="${mesh_dir}/Texture.239.dae" scale="1.00000 1.00000 1.00000"/>
      </geometry>
    </visual>
    <visual name="i01.left.bicep.full.005">
      <material name="Material.022"/>
      <origin rpy="-0.00000 0.00000 0.00000" xyz="-2.07702 0.12073 -10.83652"/>
      <geometry>
        <mesh filename="${mesh_dir}/Texture.240.dae" scale="1.00000 1.00000 1.00000"/>
      </geometry>
    </visual>
    <visual name="i01.left.bicep.full.006">
      <material name="Material.022"/>
      <origin rpy="-0.00000 0.00000 0.00000" xyz="-2.07702 0.12073 -10.83652"/>
      <geometry>
        <mesh filename="${mesh_dir}/Texture.241.dae" scale="1.00000 1.00000 1.00000"/>
      </geometry>
    </visual>
    <visual name="i01.left.bicep.full.007">
      <material name="Material.022"/>
      <origin rpy="-0.00000 0.00000 0.00000" xyz="-2.07702 0.12073 -10.83652"/>
      <geometry>
        <mesh filename="${mesh_dir}/Texture.242.dae" scale="1.00000 1.00000 1.00000"/>
      </geometry>
    </visual>
    <visual name="i01.left.bicep.full.008">
      <material name="Material.022"/>
      <origin rpy="-0.00000 0.00000 0.00000" xyz="-2.07702 0.12073 -10.83652"/>
      <geometry>
        <mesh filename="${mesh_dir}/Texture.243.dae" scale="1.00000 1.00000 1.00000"/>
      </geometry>
    </visual>
    <visual name="i01.left.bicep.full.009">
      <material name="Material.022"/>
      <origin rpy="-0.00000 0.00000 0.00000" xyz="-2.07702 0.12073 -10.83652"/>
      <geometry>
        <mesh filename="${mesh_dir}/Texture.244.dae" scale="1.00000 1.00000 1.00000"/>
      </geometry>
    </visual>
    <visual name="i01.left.bicep.full.010">
      <material name="Material.022"/>
      <origin rpy="-0.00000 0.00000 0.00000" xyz="-2.07702 0.12073 -10.83652"/>
      <geometry>
        <mesh filename="${mesh_dir}/Texture.245.dae" scale="1.00000 1.00000 1.00000"/>
      </geometry>
    </visual>
    <visual name="i01.left.bicep.full.011">
      <material name="Material.022"/>
      <origin rpy="-0.00000 0.00000 0.00000" xyz="-2.07702 0.12073 -10.83652"/>
      <geometry>
        <mesh filename="${mesh_dir}/Texture.246.dae" scale="1.00000 1.00000 1.00000"/>
      </geometry>
    </visual>
    <visual name="i01.left.bicep.full.012">
      <material name="Material.022"/>
      <origin rpy="-0.00000 0.00000 0.00000" xyz="-2.07702 0.12073 -10.83652"/>
      <geometry>
        <mesh filename="${mesh_dir}/Texture.247.dae" scale="1.00000 1.00000 1.00000"/>
      </geometry>
    </visual>
    <inertial><mass value="0.001"/><inertia ixx="1e-6" ixy="0" ixz="0" iyy="1e-6" iyz="0" izz="1e-6"/></inertial>
  </link>
  <link name="left_wrist_z_link">
    <visual name="i01.leftHand.Wristlarge">
      <material name="Material.602"/>
      <origin rpy="0.41605 0.00000 0.00000" xyz="-1.98935 4.36716 -7.14138"/>
      <geometry>
        <mesh filename="${mesh_dir}/Texture.039.dae" scale="1.00000 1.00000 1.00000"/>
      </geometry>
    </visual>
    <inertial><mass value="0.001"/><inertia ixx="1e-6" ixy="0" ixz="0" iyy="1e-6" iyz="0" izz="1e-6"/></inertial>
  </link>
  <link name="i01.leftHand.wrist.001_link">
    <visual name="i01.leftHand.Wristlarge.001">
      <material name="Material.602"/>
      <origin rpy="0.41605 -0.00000 0.61611" xyz="-4.14720 2.41462 -6.97213"/>
      <geometry>
        <mesh filename="${mesh_dir}/Texture.235.dae" scale="1.00000 1.00000 1.00000"/>
      </geometry>
    </visual>
    <inertial><mass value="0.001"/><inertia ixx="1e-6" ixy="0" ixz="0" iyy="1e-6" iyz="0" izz="1e-6"/></inertial>
  </link>
  <link name="i01.leftHand.index_link">
    <visual name="i01.leftHand.indexPhal1">
      <material name="Material.610"/>
      <origin rpy="1.98409 -0.61920 0.09256" xyz="-5.01013 5.59578 2.39863"/>
      <geometry>
        <mesh filename="${mesh_dir}/Texture.018.dae" scale="1.00000 1.00000 1.00000"/>
      </geometry>
    </visual>
    <inertial><mass value="0.001"/><inertia ixx="1e-6" ixy="0" ixz="0" iyy="1e-6" iyz="0" izz="1e-6"/></inertial>
  </link>
  <link name="torso_bottom_link">
    <visual name="i01.torso.midstom.full">
      <material name="Material.008"/>
      <origin rpy="-0.00000 -0.00000 0.00000" xyz="0.00000 0.44365 -8.97279"/>
      <geometry>
        <mesh filename="${mesh_dir}/Texture.002.dae" scale="1.00000 1.00000 1.00000"/>
      </geometry>
    </visual>
    <visual name="i01.torso.midstom.full.001">
      <material name="Material.008"/>
      <origin rpy="-0.00000 -0.00000 0.00000" xyz="0.00000 0.44365 -8.97279"/>
      <geometry>
        <mesh filename="${mesh_dir}/Texture.195.dae" scale="1.00000 1.00000 1.00000"/>
      </geometry>
    </visual>
    <visual name="i01.torso.midstom.full.002">
      <material name="Material.008"/>
      <origin rpy="-0.00000 -0.00000 0.00000" xyz="0.00000 0.44365 -8.97279"/>
      <geometry>
        <mesh filename="${mesh_dir}/Texture.196.dae" scale="1.00000 1.00000 1.00000"/>
      </geometry>
    </visual>
    <visual name="i01.torso.midstom.full.003">
      <material name="Material.008"/>
      <origin rpy="-0.00000 -0.00000 0.00000" xyz="0.00000 0.44365 -8.97279"/>
      <geometry>
        <mesh filename="${mesh_dir}/Texture.197.dae" scale="1.00000 1.00000 1.00000"/>
      </geometry>
    </visual>
    <visual name="i01.torso.midstom.full.004">
      <material name="Material.008"/>
      <origin rpy="-0.00000 -0.00000 0.00000" xyz="0.00000 0.44365 -8.97279"/>
      <geometry>
        <mesh filename="${mesh_dir}/Texture.198.dae" scale="1.00000 1.00000 1.00000"/>
      </geometry>
    </visual>
    <visual name="i01.torso.midstom.full.005">
      <material name="Material.008"/>
      <origin rpy="-0.00000 -0.00000 0.00000" xyz="0.00000 0.44365 -8.97279"/>
      <geometry>
        <mesh filename="${mesh_dir}/Texture.199.dae" scale="1.00000 1.00000 1.00000"/>
      </geometry>
    </visual>
    <visual name="i01.torso.midstom.full.006">
      <material name="Material.008"/>
      <origin rpy="-0.00000 -0.00000 0.00000" xyz="0.00000 0.44365 -8.97279"/>
      <geometry>
        <mesh filename="${mesh_dir}/Texture.200.dae" scale="1.00000 1.00000 1.00000"/>
      </geometry>
    </visual>
    <visual name="i01.torso.midstom.full.007">
      <material name="Material.008"/>
      <origin rpy="-0.00000 -0.00000 0.00000" xyz="0.00000 0.44365 -8.97279"/>
      <geometry>
        <mesh filename="${mesh_dir}/Texture.201.dae" scale="1.00000 1.00000 1.00000"/>
      </geometry>
    </visual>
    <visual name="i01.torso.midstom.full.008">
      <material name="Material.008"/>
      <origin rpy="-0.00000 -0.00000 0.00000" xyz="0.00000 0.44365 -8.97279"/>
      <geometry>
        <mesh filename="${mesh_dir}/Texture.202.dae" scale="1.00000 1.00000 1.00000"/>
      </geometry>
    </visual>
    <visual name="i01.torso.midstom.full.009">
      <material name="Material.008"/>
      <origin rpy="-0.00000 -0.00000 0.00000" xyz="0.00000 0.44365 -8.97279"/>
      <geometry>
        <mesh filename="${mesh_dir}/Texture.203.dae" scale="1.00000 1.00000 1.00000"/>
      </geometry>
    </visual>
    <!-- Minimal inertial so urdf2sdf includes this link in Gazebo (required for child links/joints) -->
    <inertial>
      <mass value="0.001"/>
      <inertia ixx="1e-6" ixy="0" ixz="0" iyy="1e-6" iyz="0" izz="1e-6"/>
    </inertial>
  </link>
  <link name="i01.leftHand.index2_link">
    <visual name="i01.leftHand.indexPhal2">
      <material name="Material.614"/>
      <origin rpy="1.98409 -0.61920 0.09256" xyz="-5.01271 5.25474 2.39178"/>
      <geometry>
        <mesh filename="${mesh_dir}/Texture.019.dae" scale="1.00000 1.00000 1.00000"/>
      </geometry>
    </visual>
    <inertial><mass value="0.001"/><inertia ixx="1e-6" ixy="0" ixz="0" iyy="1e-6" iyz="0" izz="1e-6"/></inertial>
  </link>
  <link name="i01.leftHand.index3_link">
    <visual name="i01.leftHand.indexPhal3">
      <material name="Material.618"/>
      <origin rpy="1.98408 -0.61920 0.09256" xyz="-5.01374 5.02777 2.38745"/>
      <geometry>
        <mesh filename="${mesh_dir}/Texture.020.dae" scale="1.00000 1.00000 1.00000"/>
      </geometry>
    </visual>
    <inertial><mass value="0.001"/><inertia ixx="1e-6" ixy="0" ixz="0" iyy="1e-6" iyz="0" izz="1e-6"/></inertial>
  </link>
  <link name="i01.leftHand.majeure_link">
    <visual name="i01.leftHand.majeurePhal1">
      <material name="Material.609"/>
      <origin rpy="1.98409 -0.61920 -0.00000" xyz="-4.21669 5.99551 2.39975"/>
      <geometry>
        <mesh filename="${mesh_dir}/Texture.022.dae" scale="1.00000 1.00000 1.00000"/>
      </geometry>
    </visual>
    <inertial><mass value="0.001"/><inertia ixx="1e-6" ixy="0" ixz="0" iyy="1e-6" iyz="0" izz="1e-6"/></inertial>
  </link>
  <link name="i01.leftHand.majeure2_link">
    <visual name="i01.leftHand.majeurePhal2">
      <material name="Material.613"/>
      <origin rpy="1.98409 -0.61920 -0.00000" xyz="-4.21941 5.63616 2.39254"/>
      <geometry>
        <mesh filename="${mesh_dir}/Texture.023.dae" scale="1.00000 1.00000 1.00000"/>
      </geometry>
    </visual>
    <inertial><mass value="0.001"/><inertia ixx="1e-6" ixy="0" ixz="0" iyy="1e-6" iyz="0" izz="1e-6"/></inertial>
  </link>
  <link name="i01.leftHand.majeure3_link">
    <visual name="i01.leftHand.majeurePhal3">
      <material name="Material.617"/>
      <origin rpy="1.98409 -0.61920 0.00000" xyz="-4.22050 5.39700 2.38798"/>
      <geometry>
        <mesh filename="${mesh_dir}/Texture.024.dae" scale="1.00000 1.00000 1.00000"/>
      </geometry>
    </visual>
    <inertial><mass value="0.001"/><inertia ixx="1e-6" ixy="0" ixz="0" iyy="1e-6" iyz="0" izz="1e-6"/></inertial>
  </link>
  <link name="i01.leftHand.pinky0_link">
    <visual name="i01.leftHand.WristSmall2">
      <material name="Material.601"/>
      <origin rpy="1.98409 -0.61920 0.68804" xyz="-7.22704 2.64375 2.38651"/>
      <geometry>
        <mesh filename="${mesh_dir}/Texture.041.dae" scale="1.00000 1.00000 1.00000"/>
      </geometry>
    </visual>
    <inertial><mass value="0.001"/><inertia ixx="1e-6" ixy="0" ixz="0" iyy="1e-6" iyz="0" izz="1e-6"/></inertial>
  </link>
  <link name="i01.leftHand.pinky_link">
    <visual name="i01.leftHand.pinkyPhal1">
      <material name="Material.607"/>
      <origin rpy="1.98409 -0.61920 -0.25722" xyz="-2.00181 6.93659 2.37926"/>
      <geometry>
        <mesh filename="${mesh_dir}/Texture.027.dae" scale="1.00000 1.00000 1.00000"/>
      </geometry>
    </visual>
    <inertial><mass value="0.001"/><inertia ixx="1e-6" ixy="0" ixz="0" iyy="1e-6" iyz="0" izz="1e-6"/></inertial>
  </link>
  <link name="i01.leftHand.pinky2_link">
    <visual name="i01.leftHand.pinkyPhal2">
      <material name="Material.611"/>
      <origin rpy="1.98409 -0.61921 -0.25722" xyz="-2.00407 6.63864 2.37327"/>
      <geometry>
        <mesh filename="${mesh_dir}/Texture.028.dae" scale="1.00000 1.00000 1.00000"/>
      </geometry>
    </visual>
    <inertial><mass value="0.001"/><inertia ixx="1e-6" ixy="0" ixz="0" iyy="1e-6" iyz="0" izz="1e-6"/></inertial>
  </link>
  <link name="i01.leftHand.pinky3_link">
    <visual name="i01.leftHand.pinkyPhal3">
      <material name="Material.615"/>
      <origin rpy="1.98409 -0.61920 -0.25722" xyz="-2.00497 6.44033 2.36951"/>
      <geometry>
        <mesh filename="${mesh_dir}/Texture.029.dae" scale="1.00000 1.00000 1.00000"/>
      </geometry>
    </visual>
    <inertial><mass value="0.001"/><inertia ixx="1e-6" ixy="0" ixz="0" iyy="1e-6" iyz="0" izz="1e-6"/></inertial>
  </link>
  <link name="i01.leftHand.ringfinger0_link">
    <visual name="i01.leftHand.WristSmall">
      <material name="Material.606"/>
      <origin rpy="1.98409 -0.61920 0.68804" xyz="-7.22704 2.35455 2.38651"/>
      <geometry>
        <mesh filename="${mesh_dir}/Texture.040.dae" scale="1.00000 1.00000 1.00000"/>
      </geometry>
    </visual>
    <inertial><mass value="0.001"/><inertia ixx="1e-6" ixy="0" ixz="0" iyy="1e-6" iyz="0" izz="1e-6"/></inertial>
  </link>
  <link name="torso_z_link">
    <visual name="i01.torso.topStom.full">
      <material name="Material.007"/>
      <origin rpy="0.06589 0.00000 -1.57080" xyz="1.05285 -0.00213 -10.06338"/>
      <geometry>
        <mesh filename="${mesh_dir}/Texture.001.dae" scale="1.00000 1.00000 1.00000"/>
      </geometry>
    </visual>
    <visual name="i01.torso.topStom.full.001">
      <material name="Material.007"/>
      <origin rpy="0.06589 0.00000 -1.57080" xyz="1.05285 -0.00213 -10.06338"/>
      <geometry>
        <mesh filename="${mesh_dir}/Texture.167.dae" scale="1.00000 1.00000 1.00000"/>
      </geometry>
    </visual>
    <visual name="i01.torso.topStom.full.002">
      <material name="Material.007"/>
      <origin rpy="0.06589 0.00000 -1.57080" xyz="1.05285 -0.00213 -10.06338"/>
      <geometry>
        <mesh filename="${mesh_dir}/Texture.168.dae" scale="1.00000 1.00000 1.00000"/>
      </geometry>
    </visual>
    <visual name="i01.torso.topStom.full.003">
      <material name="Material.007"/>
      <origin rpy="0.06589 0.00000 -1.57080" xyz="1.05285 -0.00213 -10.06338"/>
      <geometry>
        <mesh filename="${mesh_dir}/Texture.169.dae" scale="1.00000 1.00000 1.00000"/>
      </geometry>
    </visual>
    <visual name="i01.torso.topStom.full.004">
      <material name="Material.007"/>
      <origin rpy="0.06589 0.00000 -1.57080" xyz="1.05285 -0.00213 -10.06338"/>
      <geometry>
        <mesh filename="${mesh_dir}/Texture.170.dae" scale="1.00000 1.00000 1.00000"/>
      </geometry>
    </visual>
    <visual name="i01.torso.topStom.full.005">
      <material name="Material.007"/>
      <origin rpy="0.06589 0.00000 -1.57080" xyz="1.05285 -0.00213 -10.06338"/>
      <geometry>
        <mesh filename="${mesh_dir}/Texture.171.dae" scale="1.00000 1.00000 1.00000"/>
      </geometry>
    </visual>
    <visual name="i01.torso.topStom.full.006">
      <material name="Material.007"/>
      <origin rpy="0.06589 0.00000 -1.57080" xyz="1.05285 -0.00213 -10.06338"/>
      <geometry>
        <mesh filename="${mesh_dir}/Texture.172.dae" scale="1.00000 1.00000 1.00000"/>
      </geometry>
    </visual>
    <visual name="i01.torso.topStom.full.007">
      <material name="Material.007"/>
      <origin rpy="0.06589 0.00000 -1.57080" xyz="1.05285 -0.00213 -10.06338"/>
      <geometry>
        <mesh filename="${mesh_dir}/Texture.173.dae" scale="1.00000 1.00000 1.00000"/>
      </geometry>
    </visual>
    <visual name="i01.torso.topStom.full.008">
      <material name="Material.007"/>
      <origin rpy="0.06589 0.00000 -1.57080" xyz="1.05285 -0.00213 -10.06338"/>
      <geometry>
        <mesh filename="${mesh_dir}/Texture.174.dae" scale="1.00000 1.00000 1.00000"/>
      </geometry>
    </visual>
    <visual name="i01.torso.topStom.full.009">
      <material name="Material.007"/>
      <origin rpy="0.06589 0.00000 -1.57080" xyz="1.05285 -0.00213 -10.06338"/>
      <geometry>
        <mesh filename="${mesh_dir}/Texture.175.dae" scale="1.00000 1.00000 1.00000"/>
      </geometry>
    </visual>
    <visual name="i01.torso.topStom.full.010">
      <material name="Material.007"/>
      <origin rpy="0.06589 0.00000 -1.57080" xyz="1.05285 -0.00213 -10.06338"/>
      <geometry>
        <mesh filename="${mesh_dir}/Texture.176.dae" scale="1.00000 1.00000 1.00000"/>
      </geometry>
    </visual>
    <visual name="i01.torso.topStom.full.011">
      <material name="Material.007"/>
      <origin rpy="0.06589 0.00000 -1.57080" xyz="1.05285 -0.00213 -10.06338"/>
      <geometry>
        <mesh filename="${mesh_dir}/Texture.177.dae" scale="1.00000 1.00000 1.00000"/>
      </geometry>
    </visual>
    <visual name="i01.torso.topStom.full.012">
      <material name="Material.007"/>
      <origin rpy="0.06589 0.00000 -1.57080" xyz="1.05285 -0.00213 -10.06338"/>
      <geometry>
        <mesh filename="${mesh_dir}/Texture.178.dae" scale="1.00000 1.00000 1.00000"/>
      </geometry>
    </visual>
    <visual name="i01.torso.topStom.full.013">
      <material name="Material.007"/>
      <origin rpy="0.06589 0.00000 -1.57080" xyz="1.05285 -0.00213 -10.06338"/>
      <geometry>
        <mesh filename="${mesh_dir}/Texture.179.dae" scale="1.00000 1.00000 1.00000"/>
      </geometry>
    </visual>
    <visual name="i01.torso.topStom.full.014">
      <material name="Material.007"/>
      <origin rpy="0.06589 0.00000 -1.57080" xyz="1.05285 -0.00213 -10.06338"/>
      <geometry>
        <mesh filename="${mesh_dir}/Texture.180.dae" scale="1.00000 1.00000 1.00000"/>
      </geometry>
    </visual>
    <visual name="i01.torso.topStom.full.015">
      <material name="Material.007"/>
      <origin rpy="0.06589 0.00000 -1.57080" xyz="1.05285 -0.00213 -10.06338"/>
      <geometry>
        <mesh filename="${mesh_dir}/Texture.181.dae" scale="1.00000 1.00000 1.00000"/>
      </geometry>
    </visual>
    <visual name="i01.torso.topStom.full.016">
      <material name="Material.007"/>
      <origin rpy="0.06589 0.00000 -1.57080" xyz="1.05285 -0.00213 -10.06338"/>
      <geometry>
        <mesh filename="${mesh_dir}/Texture.182.dae" scale="1.00000 1.00000 1.00000"/>
      </geometry>
    </visual>
    <visual name="i01.torso.topStom.full.017">
      <material name="Material.007"/>
      <origin rpy="0.06589 0.00000 -1.57080" xyz="1.05285 -0.00213 -10.06338"/>
      <geometry>
        <mesh filename="${mesh_dir}/Texture.183.dae" scale="1.00000 1.00000 1.00000"/>
      </geometry>
    </visual>
    <visual name="i01.torso.topStom.full.018">
      <material name="Material.007"/>
      <origin rpy="0.06589 0.00000 -1.57080" xyz="1.05285 -0.00213 -10.06338"/>
      <geometry>
        <mesh filename="${mesh_dir}/Texture.184.dae" scale="1.00000 1.00000 1.00000"/>
      </geometry>
    </visual>
    <visual name="i01.torso.topStom.full.019">
      <material name="Material.007"/>
      <origin rpy="0.06589 0.00000 -1.57080" xyz="1.05285 -0.00213 -10.06338"/>
      <geometry>
        <mesh filename="${mesh_dir}/Texture.185.dae" scale="1.00000 1.00000 1.00000"/>
      </geometry>
    </visual>
    <visual name="i01.torso.topStom.full.020">
      <material name="Material.007"/>
      <origin rpy="0.06589 0.00000 -1.57080" xyz="1.05285 -0.00213 -10.06338"/>
      <geometry>
        <mesh filename="${mesh_dir}/Texture.186.dae" scale="1.00000 1.00000 1.00000"/>
      </geometry>
    </visual>
    <visual name="i01.torso.topStom.full.021">
      <material name="Material.007"/>
      <origin rpy="0.06589 0.00000 -1.57080" xyz="1.05285 -0.00213 -10.06338"/>
      <geometry>
        <mesh filename="${mesh_dir}/Texture.187.dae" scale="1.00000 1.00000 1.00000"/>
      </geometry>
    </visual>
    <visual name="i01.torso.topStom.full.022">
      <material name="Material.007"/>
      <origin rpy="0.06589 0.00000 -1.57080" xyz="1.05285 -0.00213 -10.06338"/>
      <geometry>
        <mesh filename="${mesh_dir}/Texture.188.dae" scale="1.00000 1.00000 1.00000"/>
      </geometry>
    </visual>
    <visual name="i01.torso.topStom.full.023">
      <material name="Material.007"/>
      <origin rpy="0.06589 0.00000 -1.57080" xyz="1.05285 -0.00213 -10.06338"/>
      <geometry>
        <mesh filename="${mesh_dir}/Texture.189.dae" scale="1.00000 1.00000 1.00000"/>
      </geometry>
    </visual>
    <visual name="i01.torso.topStom.full.024">
      <material name="Material.007"/>
      <origin rpy="0.06589 0.00000 -1.57080" xyz="1.05285 -0.00213 -10.06338"/>
      <geometry>
        <mesh filename="${mesh_dir}/Texture.190.dae" scale="1.00000 1.00000 1.00000"/>
      </geometry>
    </visual>
    <visual name="i01.torso.topStom.full.025">
      <material name="Material.007"/>
      <origin rpy="0.06589 0.00000 -1.57080" xyz="1.05285 -0.00213 -10.06338"/>
      <geometry>
        <mesh filename="${mesh_dir}/Texture.191.dae" scale="1.00000 1.00000 1.00000"/>
      </geometry>
    </visual>
    <visual name="i01.torso.topStom.full.026">
      <material name="Material.007"/>
      <origin rpy="0.06589 0.00000 -1.57080" xyz="1.05285 -0.00213 -10.06338"/>
      <geometry>
        <mesh filename="${mesh_dir}/Texture.192.dae" scale="1.00000 1.00000 1.00000"/>
      </geometry>
    </visual>
    <visual name="i01.torso.topStom.full.027">
      <material name="Material.007"/>
      <origin rpy="0.06589 0.00000 -1.57080" xyz="1.05285 -0.00213 -10.06338"/>
      <geometry>
        <mesh filename="${mesh_dir}/Texture.193.dae" scale="1.00000 1.00000 1.00000"/>
      </geometry>
    </visual>
    <visual name="i01.torso.topStom.full.028">
      <material name="Material.007"/>
      <origin rpy="0.06589 0.00000 -1.57080" xyz="1.05285 -0.00213 -10.06338"/>
      <geometry>
        <mesh filename="${mesh_dir}/Texture.194.dae" scale="1.00000 1.00000 1.00000"/>
      </geometry>
    </visual>
    <!-- Minimal inertial so urdf2sdf includes this link in Gazebo -->
    <inertial>
      <mass value="0.001"/>
      <inertia ixx="1e-6" ixy="0" ixz="0" iyy="1e-6" iyz="0" izz="1e-6"/>
    </inertial>
  </link>
  <link name="i01.leftHand.ringFinger_link">
    <visual name="i01.leftHand.ringFingerPhal1">
      <material name="Material.608"/>
      <origin rpy="1.98409 -0.61920 -0.08681" xyz="-3.38539 6.39614 2.39315"/>
      <geometry>
        <mesh filename="${mesh_dir}/Texture.032.dae" scale="1.00000 1.00000 1.00000"/>
      </geometry>
    </visual>
    <inertial><mass value="0.001"/><inertia ixx="1e-6" ixy="0" ixz="0" iyy="1e-6" iyz="0" izz="1e-6"/></inertial>
  </link>
  <link name="i01.leftHand.ringfinger2_link">
    <visual name="i01.leftHand.ringFingerPhal2">
      <material name="Material.612"/>
      <origin rpy="1.98409 -0.61920 -0.08682" xyz="-3.38797 6.05509 2.38632"/>
      <geometry>
        <mesh filename="${mesh_dir}/Texture.033.dae" scale="1.00000 1.00000 1.00000"/>
      </geometry>
    </visual>
    <inertial><mass value="0.001"/><inertia ixx="1e-6" ixy="0" ixz="0" iyy="1e-6" iyz="0" izz="1e-6"/></inertial>
  </link>
  <link name="i01.leftHand.ringfinger3_link">
    <visual name="i01.leftHand.ringFingerPhal3">
      <material name="Material.616"/>
      <origin rpy="1.98409 -0.61920 -0.08682" xyz="-3.38900 5.82812 2.38200"/>
      <geometry>
        <mesh filename="${mesh_dir}/Texture.034.dae" scale="1.00000 1.00000 1.00000"/>
      </geometry>
    </visual>
    <inertial><mass value="0.001"/><inertia ixx="1e-6" ixy="0" ixz="0" iyy="1e-6" iyz="0" izz="1e-6"/></inertial>
  </link>
  <link name="i01.leftHand.thumb1_link">
    <visual name="i01.leftHand.ThumbBase">
      <material name="Material.603"/>
      <origin rpy="-1.08797 0.62375 -0.06004" xyz="-5.06759 -5.98847 -2.72986"/>
      <geometry>
        <mesh filename="${mesh_dir}/Texture.035.dae" scale="1.00000 1.00000 1.00000"/>
      </geometry>
    </visual>
    <inertial><mass value="0.001"/><inertia ixx="1e-6" ixy="0" ixz="0" iyy="1e-6" iyz="0" izz="1e-6"/></inertial>
  </link>
  <link name="i01.leftHand.thumb_link">
    <visual name="i01.leftHand.ThumbMid">
      <material name="Material.604"/>
      <origin rpy="-1.43268 0.82776 -1.11670" xyz="-8.37077 -0.01374 -0.04665"/>
      <geometry>
        <mesh filename="${mesh_dir}/Texture.037.dae" scale="1.00000 1.00000 1.00000"/>
      </geometry>
    </visual>
    <inertial><mass value="0.001"/><inertia ixx="1e-6" ixy="0" ixz="0" iyy="1e-6" iyz="0" izz="1e-6"/></inertial>
  </link>
  <link name="i01.leftHand.thumb3_link">
    <visual name="i01.leftHand.ThumbTip">
      <material name="Material.605"/>
      <origin rpy="-1.43269 0.82776 -1.11671" xyz="-8.38306 0.31675 -0.03957"/>
      <geometry>
        <mesh filename="${mesh_dir}/Texture.038.dae" scale="1.00000 1.00000 1.00000"/>
      </geometry>
    </visual>
    <inertial><mass value="0.001"/><inertia ixx="1e-6" ixy="0" ixz="0" iyy="1e-6" iyz="0" izz="1e-6"/></inertial>
  </link>
  <link name="right_shoulder_y_link">
    <visual name="i01.rightArm.omoplate.full">
      <material name="Material.016"/>
      <origin rpy="0.06568 -0.00000 -0.00000" xyz="1.35226 1.11648 -13.89026"/>
      <geometry>
        <mesh filename="${mesh_dir}/Texture.006.dae" scale="1.00000 1.00000 1.00000"/>
      </geometry>
    </visual>
    <visual name="i01.rightArm.omoplate.full.001">
      <material name="Material.016"/>
      <origin rpy="0.06568 -0.00000 -0.00000" xyz="1.35226 1.11648 -13.89026"/>
      <geometry>
        <mesh filename="${mesh_dir}/Texture.217.dae" scale="1.00000 1.00000 1.00000"/>
      </geometry>
    </visual>
    <visual name="i01.rightArm.omoplate.full.002">
      <material name="Material.016"/>
      <origin rpy="0.06568 -0.00000 -0.00000" xyz="1.35226 1.11648 -13.89026"/>
      <geometry>
        <mesh filename="${mesh_dir}/Texture.218.dae" scale="1.00000 1.00000 1.00000"/>
      </geometry>
    </visual>
    <visual name="i01.rightArm.omoplate.full.003">
      <material name="Material.016"/>
      <origin rpy="0.06568 -0.00000 -0.00000" xyz="1.35226 1.11648 -13.89026"/>
      <geometry>
        <mesh filename="${mesh_dir}/Texture.219.dae" scale="1.00000 1.00000 1.00000"/>
      </geometry>
    </visual>
    <visual name="i01.rightArm.omoplate.full.004">
      <material name="Material.016"/>
      <origin rpy="0.06568 -0.00000 -0.00000" xyz="1.35226 1.11648 -13.89026"/>
      <geometry>
        <mesh filename="${mesh_dir}/Texture.220.dae" scale="1.00000 1.00000 1.00000"/>
      </geometry>
    </visual>
    <visual name="i01.rightArm.omoplate.full.005">
      <material name="Material.016"/>
      <origin rpy="0.06568 -0.00000 -0.00000" xyz="1.35226 1.11648 -13.89026"/>
      <geometry>
        <mesh filename="${mesh_dir}/Texture.221.dae" scale="1.00000 1.00000 1.00000"/>
      </geometry>
    </visual>
    <visual name="i01.rightArm.omoplate.full.006">
      <material name="Material.016"/>
      <origin rpy="0.06568 -0.00000 -0.00000" xyz="1.35226 1.11648 -13.89026"/>
      <geometry>
        <mesh filename="${mesh_dir}/Texture.222.dae" scale="1.00000 1.00000 1.00000"/>
      </geometry>
    </visual>
    <inertial><mass value="0.001"/><inertia ixx="1e-6" ixy="0" ixz="0" iyy="1e-6" iyz="0" izz="1e-6"/></inertial>
  </link>
  <link name="right_shoulder_x_link">
    <visual name="i01.rightArm.shoulder.full">
      <material name="Material.238"/>
      <origin rpy="-0.06568 -0.00000 -3.14159" xyz="1.46576 1.11459 -13.51522"/>
      <geometry>
        <mesh filename="${mesh_dir}/Texture.005.dae" scale="1.00000 1.00000 1.00000"/>
      </geometry>
    </visual>
    <visual name="i01.rightArm.shoulder.full.001">
      <material name="Material.238"/>
      <origin rpy="-0.06568 -0.00000 -3.14159" xyz="1.46576 1.11459 -13.51522"/>
      <geometry>
        <mesh filename="${mesh_dir}/Texture.223.dae" scale="1.00000 1.00000 1.00000"/>
      </geometry>
    </visual>
    <visual name="i01.rightArm.shoulder.full.002">
      <material name="Material.238"/>
      <origin rpy="-0.06568 -0.00000 -3.14159" xyz="1.46576 1.11459 -13.51522"/>
      <geometry>
        <mesh filename="${mesh_dir}/Texture.224.dae" scale="1.00000 1.00000 1.00000"/>
      </geometry>
    </visual>
    <visual name="i01.rightArm.shoulder.full.003">
      <material name="Material.238"/>
      <origin rpy="-0.06568 -0.00000 -3.14159" xyz="1.46576 1.11459 -13.51522"/>
      <geometry>
        <mesh filename="${mesh_dir}/Texture.225.dae" scale="1.00000 1.00000 1.00000"/>
      </geometry>
    </visual>
    <visual name="i01.rightArm.shoulder.full.004">
      <material name="Material.238"/>
      <origin rpy="-0.06568 -0.00000 -3.14159" xyz="1.46576 1.11459 -13.51522"/>
      <geometry>
        <mesh filename="${mesh_dir}/Texture.226.dae" scale="1.00000 1.00000 1.00000"/>
      </geometry>
    </visual>
    <visual name="i01.rightArm.shoulder.full.005">
      <material name="Material.012"/>
      <origin rpy="-0.06568 -0.00000 -3.14159" xyz="1.46576 1.11459 -13.51522"/>
      <geometry>
        <mesh filename="${mesh_dir}/Texture.227.dae" scale="1.00000 1.00000 1.00000"/>
      </geometry>
    </visual>
    <visual name="i01.rightArm.shoulder.full.006">
      <material name="Material.238"/>
      <origin rpy="-0.06568 -0.00000 -3.14159" xyz="1.46576 1.11459 -13.51522"/>
      <geometry>
        <mesh filename="${mesh_dir}/Texture.228.dae" scale="1.00000 1.00000 1.00000"/>
      </geometry>
    </visual>
    <visual name="i01.rightArm.shoulder.full.007">
      <material name="Material.238"/>
      <origin rpy="-0.06568 -0.00000 -3.14159" xyz="1.46576 1.11459 -13.51522"/>
      <geometry>
        <mesh filename="${mesh_dir}/Texture.229.dae" scale="1.00000 1.00000 1.00000"/>
      </geometry>
    </visual>
    <visual name="i01.rightArm.shoulder.full.008">
      <material name="Material.238"/>
      <origin rpy="-0.06568 -0.00000 -3.14159" xyz="1.46576 1.11459 -13.51522"/>
      <geometry>
        <mesh filename="${mesh_dir}/Texture.230.dae" scale="1.00000 1.00000 1.00000"/>
      </geometry>
    </visual>
    <visual name="i01.rightArm.shoulder.full.009">
      <material name="Material.238"/>
      <origin rpy="-0.06568 -0.00000 -3.14159" xyz="1.46576 1.11459 -13.51522"/>
      <geometry>
        <mesh filename="${mesh_dir}/Texture.231.dae" scale="1.00000 1.00000 1.00000"/>
      </geometry>
    </visual>
    <visual name="i01.rightArm.shoulder.full.011">
      <material name="Material.238"/>
      <origin rpy="-0.06568 -0.00000 -3.14159" xyz="1.46576 1.11459 -13.51522"/>
      <geometry>
        <mesh filename="${mesh_dir}/Texture.233.dae" scale="1.00000 1.00000 1.00000"/>
      </geometry>
    </visual>
    <visual name="i01.rightArm.shoulder.full.012">
      <material name="Material.238"/>
      <origin rpy="-0.06568 -0.00000 -3.14159" xyz="1.46576 1.11459 -13.51522"/>
      <geometry>
        <mesh filename="${mesh_dir}/Texture.234.dae" scale="1.00000 1.00000 1.00000"/>
      </geometry>
    </visual>
    <inertial><mass value="0.001"/><inertia ixx="1e-6" ixy="0" ixz="0" iyy="1e-6" iyz="0" izz="1e-6"/></inertial>
  </link>
  <link name="right_shoulder_z_link">
    <visual name="i01.rightArm.rotate.full">
      <material name="[0131_Silver]"/>
      <origin rpy="3.13367 0.00000 0.00000" xyz="2.08983 1.12392 -12.92101"/>
      <geometry>
        <mesh filename="${mesh_dir}/G-__566220.dae" scale="1.00000 1.00000 1.00000"/>
      </geometry>
    </visual>
    <visual name="i01.rightArm.rotate.full.001">
      <material name="[0131_Silver]"/>
      <origin rpy="3.13367 0.00000 0.00000" xyz="2.08983 1.12392 -12.92101"/>
      <geometry>
        <mesh filename="${mesh_dir}/G-__566220.001.dae" scale="1.00000 1.00000 1.00000"/>
      </geometry>
    </visual>
    <visual name="i01.rightArm.rotate.full.002">
      <material name="[0131_Silver]"/>
      <origin rpy="3.13367 0.00000 0.00000" xyz="2.08983 1.12392 -12.92101"/>
      <geometry>
        <mesh filename="${mesh_dir}/G-__566220.002.dae" scale="1.00000 1.00000 1.00000"/>
      </geometry>
    </visual>
    <visual name="i01.rightArm.rotate.full.003">
      <material name="[0131_Silver]"/>
      <origin rpy="3.13367 0.00000 0.00000" xyz="2.08983 1.12392 -12.92101"/>
      <geometry>
        <mesh filename="${mesh_dir}/G-__566220.003.dae" scale="1.00000 1.00000 1.00000"/>
      </geometry>
    </visual>
    <visual name="i01.rightArm.rotate.full.004">
      <material name="[0131_Silver]"/>
      <origin rpy="3.13367 0.00000 0.00000" xyz="2.08983 1.12392 -12.92101"/>
      <geometry>
        <mesh filename="${mesh_dir}/G-__566220.004.dae" scale="1.00000 1.00000 1.00000"/>
      </geometry>
    </visual>
    <visual name="i01.rightArm.rotate.full.005">
      <material name="[0131_Silver]"/>
      <origin rpy="3.13367 0.00000 0.00000" xyz="2.08983 1.12392 -12.92101"/>
      <geometry>
        <mesh filename="${mesh_dir}/G-__566220.005.dae" scale="1.00000 1.00000 1.00000"/>
      </geometry>
    </visual>
    <visual name="i01.rightArm.rotate.full.006">
      <material name="[0131_Silver]"/>
      <origin rpy="3.13367 0.00000 0.00000" xyz="2.08983 1.12392 -12.92101"/>
      <geometry>
        <mesh filename="${mesh_dir}/G-__566220.006.dae" scale="1.00000 1.00000 1.00000"/>
      </geometry>
    </visual>
    <visual name="i01.rightArm.rotate.full.007">
      <material name="[0131_Silver]"/>
      <origin rpy="3.13367 0.00000 0.00000" xyz="2.08983 1.12392 -12.92101"/>
      <geometry>
        <mesh filename="${mesh_dir}/G-__566220.007.dae" scale="1.00000 1.00000 1.00000"/>
      </geometry>
    </visual>
    <visual name="i01.rightArm.rotate.full.008">
      <material name="[0131_Silver]"/>
      <origin rpy="3.13367 0.00000 0.00000" xyz="2.08983 1.12392 -12.92101"/>
      <geometry>
        <mesh filename="${mesh_dir}/G-__566220.008.dae" scale="1.00000 1.00000 1.00000"/>
      </geometry>
    </visual>
    <visual name="i01.rightArm.rotate.full.009">
      <material name="[0131_Silver]"/>
      <origin rpy="3.13367 0.00000 0.00000" xyz="2.08983 1.12392 -12.92101"/>
      <geometry>
        <mesh filename="${mesh_dir}/G-__566220.009.dae" scale="1.00000 1.00000 1.00000"/>
      </geometry>
    </visual>
    <visual name="i01.rightArm.rotate.full.010">
      <material name="[0131_Silver]"/>
      <origin rpy="3.13367 0.00000 0.00000" xyz="2.08983 1.12392 -12.92101"/>
      <geometry>
        <mesh filename="${mesh_dir}/G-__566220.010.dae" scale="1.00000 1.00000 1.00000"/>
      </geometry>
    </visual>
    <visual name="i01.rightArm.rotate.full.011">
      <material name="[0131_Silver]"/>
      <origin rpy="3.13367 0.00000 0.00000" xyz="2.08983 1.12392 -12.92101"/>
      <geometry>
        <mesh filename="${mesh_dir}/G-__566220.011.dae" scale="1.00000 1.00000 1.00000"/>
      </geometry>
    </visual>
    <visual name="i01.rightArm.rotate.full.012">
      <material name="[0131_Silver]"/>
      <origin rpy="3.13367 0.00000 0.00000" xyz="2.08983 1.12392 -12.92101"/>
      <geometry>
        <mesh filename="${mesh_dir}/G-__566220.012.dae" scale="1.00000 1.00000 1.00000"/>
      </geometry>
    </visual>
    <visual name="i01.rightArm.rotate.full.013">
      <material name="[0131_Silver]"/>
      <origin rpy="3.13367 0.00000 0.00000" xyz="2.08983 1.12392 -12.92101"/>
      <geometry>
        <mesh filename="${mesh_dir}/G-__566220.013.dae" scale="1.00000 1.00000 1.00000"/>
      </geometry>
    </visual>
    <visual name="i01.rightArm.rotate.full.014">
      <material name="[0131_Silver]"/>
      <origin rpy="3.13367 0.00000 0.00000" xyz="2.08983 1.12392 -12.92101"/>
      <geometry>
        <mesh filename="${mesh_dir}/G-__566220.014.dae" scale="1.00000 1.00000 1.00000"/>
      </geometry>
    </visual>
    <visual name="i01.rightArm.rotate.full.015">
      <material name="[0131_Silver]"/>
      <origin rpy="3.13367 0.00000 0.00000" xyz="2.08983 1.12392 -12.92101"/>
      <geometry>
        <mesh filename="${mesh_dir}/G-__566220.015.dae" scale="1.00000 1.00000 1.00000"/>
      </geometry>
    </visual>
    <visual name="i01.rightArm.rotate.full.016">
      <material name="[0131_Silver]"/>
      <origin rpy="3.13367 0.00000 0.00000" xyz="2.08983 1.12392 -12.92101"/>
      <geometry>
        <mesh filename="${mesh_dir}/G-__566220.016.dae" scale="1.00000 1.00000 1.00000"/>
      </geometry>
    </visual>
    <visual name="i01.rightArm.rotate.full.017">
      <material name="[0131_Silver]"/>
      <origin rpy="3.13367 0.00000 0.00000" xyz="2.08983 1.12392 -12.92101"/>
      <geometry>
        <mesh filename="${mesh_dir}/G-__566220.017.dae" scale="1.00000 1.00000 1.00000"/>
      </geometry>
    </visual>
    <visual name="i01.rightArm.rotate.full.018">
      <material name="[0131_Silver]"/>
      <origin rpy="3.13367 0.00000 0.00000" xyz="2.08983 1.12392 -12.92101"/>
      <geometry>
        <mesh filename="${mesh_dir}/G-__566220.018.dae" scale="1.00000 1.00000 1.00000"/>
      </geometry>
    </visual>
    <visual name="i01.rightArm.rotate.full.019">
      <material name="[0131_Silver]"/>
      <origin rpy="3.13367 0.00000 0.00000" xyz="2.08983 1.12392 -12.92101"/>
      <geometry>
        <mesh filename="${mesh_dir}/G-__566220.019.dae" scale="1.00000 1.00000 1.00000"/>
      </geometry>
    </visual>
    <inertial><mass value="0.001"/><inertia ixx="1e-6" ixy="0" ixz="0" iyy="1e-6" iyz="0" izz="1e-6"/></inertial>
  </link>
  <link name="right_elbow_x_link">
    <visual name="i01.right.bicep.full">
      <material name="Material.031"/>
      <origin rpy="-0.00000 -0.00000 0.00000" xyz="2.08125 0.12073 -10.83653"/>
      <geometry>
        <mesh filename="${mesh_dir}/Texture.008.dae" scale="1.00000 1.00000 1.00000"/>
      </geometry>
    </visual>
    <visual name="i01.right.bicep.full.001">
      <material name="Material.031"/>
      <origin rpy="-0.00000 -0.00000 0.00000" xyz="2.08125 0.12073 -10.83653"/>
      <geometry>
        <mesh filename="${mesh_dir}/Texture.205.dae" scale="1.00000 1.00000 1.00000"/>
      </geometry>
    </visual>
    <visual name="i01.right.bicep.full.002">
      <material name="Material.031"/>
      <origin rpy="-0.00000 -0.00000 0.00000" xyz="2.08125 0.12073 -10.83653"/>
      <geometry>
        <mesh filename="${mesh_dir}/Texture.206.dae" scale="1.00000 1.00000 1.00000"/>
      </geometry>
    </visual>
    <visual name="i01.right.bicep.full.003">
      <material name="Material.031"/>
      <origin rpy="-0.00000 -0.00000 0.00000" xyz="2.08125 0.12073 -10.83653"/>
      <geometry>
        <mesh filename="${mesh_dir}/Texture.207.dae" scale="1.00000 1.00000 1.00000"/>
      </geometry>
    </visual>
    <visual name="i01.right.bicep.full.004">
      <material name="Material.031"/>
      <origin rpy="-0.00000 -0.00000 0.00000" xyz="2.08125 0.12073 -10.83653"/>
      <geometry>
        <mesh filename="${mesh_dir}/Texture.208.dae" scale="1.00000 1.00000 1.00000"/>
      </geometry>
    </visual>
    <visual name="i01.right.bicep.full.005">
      <material name="Material.031"/>
      <origin rpy="-0.00000 -0.00000 0.00000" xyz="2.08125 0.12073 -10.83653"/>
      <geometry>
        <mesh filename="${mesh_dir}/Texture.209.dae" scale="1.00000 1.00000 1.00000"/>
      </geometry>
    </visual>
    <visual name="i01.right.bicep.full.006">
      <material name="Material.031"/>
      <origin rpy="-0.00000 -0.00000 0.00000" xyz="2.08125 0.12073 -10.83653"/>
      <geometry>
        <mesh filename="${mesh_dir}/Texture.210.dae" scale="1.00000 1.00000 1.00000"/>
      </geometry>
    </visual>
    <visual name="i01.right.bicep.full.007">
      <material name="Material.031"/>
      <origin rpy="-0.00000 -0.00000 0.00000" xyz="2.08125 0.12073 -10.83653"/>
      <geometry>
        <mesh filename="${mesh_dir}/Texture.211.dae" scale="1.00000 1.00000 1.00000"/>
      </geometry>
    </visual>
    <visual name="i01.right.bicep.full.008">
      <material name="Material.031"/>
      <origin rpy="-0.00000 -0.00000 0.00000" xyz="2.08125 0.12073 -10.83653"/>
      <geometry>
        <mesh filename="${mesh_dir}/Texture.212.dae" scale="1.00000 1.00000 1.00000"/>
      </geometry>
    </visual>
    <visual name="i01.right.bicep.full.009">
      <material name="Material.031"/>
      <origin rpy="-0.00000 -0.00000 0.00000" xyz="2.08125 0.12073 -10.83653"/>
      <geometry>
        <mesh filename="${mesh_dir}/Texture.213.dae" scale="1.00000 1.00000 1.00000"/>
      </geometry>
    </visual>
    <visual name="i01.right.bicep.full.010">
      <material name="Material.031"/>
      <origin rpy="-0.00000 -0.00000 0.00000" xyz="2.08125 0.12073 -10.83653"/>
      <geometry>
        <mesh filename="${mesh_dir}/Texture.214.dae" scale="1.00000 1.00000 1.00000"/>
      </geometry>
    </visual>
    <visual name="i01.right.bicep.full.011">
      <material name="Material.031"/>
      <origin rpy="-0.00000 -0.00000 0.00000" xyz="2.08125 0.12073 -10.83653"/>
      <geometry>
        <mesh filename="${mesh_dir}/Texture.215.dae" scale="1.00000 1.00000 1.00000"/>
      </geometry>
    </visual>
    <visual name="i01.right.bicep.full.012">
      <material name="Material.031"/>
      <origin rpy="-0.00000 -0.00000 0.00000" xyz="2.08125 0.12073 -10.83653"/>
      <geometry>
        <mesh filename="${mesh_dir}/Texture.216.dae" scale="1.00000 1.00000 1.00000"/>
      </geometry>
    </visual>
    <inertial><mass value="0.001"/><inertia ixx="1e-6" ixy="0" ixz="0" iyy="1e-6" iyz="0" izz="1e-6"/></inertial>
  </link>
  <link name="torso_y_link">
    <visual name="i01.torso.full">
      <material name="Material.026"/>
      <origin rpy="0.06589 -0.00000 -0.00000" xyz="0.00246 1.11602 -11.08254"/>
      <geometry>
        <mesh filename="${mesh_dir}/Texture.dae" scale="1.00000 1.00000 1.00000"/>
      </geometry>
    </visual>
    <visual name="i01.torso.full.001">
      <material name="Material.026"/>
      <origin rpy="0.06589 -0.00000 -0.00000" xyz="0.00246 1.11602 -11.08254"/>
      <geometry>
        <mesh filename="${mesh_dir}/Texture.088.dae" scale="1.00000 1.00000 1.00000"/>
      </geometry>
    </visual>
    <visual name="i01.torso.full.002">
      <material name="Material.026"/>
      <origin rpy="0.06589 -0.00000 -0.00000" xyz="0.00246 1.11602 -11.08254"/>
      <geometry>
        <mesh filename="${mesh_dir}/Texture.089.dae" scale="1.00000 1.00000 1.00000"/>
      </geometry>
    </visual>
    <visual name="i01.torso.full.003">
      <material name="Material.026"/>
      <origin rpy="0.06589 -0.00000 -0.00000" xyz="0.00246 1.11602 -11.08254"/>
      <geometry>
        <mesh filename="${mesh_dir}/Texture.090.dae" scale="1.00000 1.00000 1.00000"/>
      </geometry>
    </visual>
    <visual name="i01.torso.full.004">
      <material name="Material.026"/>
      <origin rpy="0.06589 -0.00000 -0.00000" xyz="0.00246 1.11602 -11.08254"/>
      <geometry>
        <mesh filename="${mesh_dir}/Texture.091.dae" scale="1.00000 1.00000 1.00000"/>
      </geometry>
    </visual>
    <visual name="i01.torso.full.005">
      <material name="Material.026"/>
      <origin rpy="0.06589 -0.00000 -0.00000" xyz="0.00246 1.11602 -11.08254"/>
      <geometry>
        <mesh filename="${mesh_dir}/Texture.092.dae" scale="1.00000 1.00000 1.00000"/>
      </geometry>
    </visual>
    <visual name="i01.torso.full.006">
      <material name="Material.026"/>
      <origin rpy="0.06589 -0.00000 -0.00000" xyz="0.00246 1.11602 -11.08254"/>
      <geometry>
        <mesh filename="${mesh_dir}/Texture.093.dae" scale="1.00000 1.00000 1.00000"/>
      </geometry>
    </visual>
    <visual name="i01.torso.full.007">
      <material name="Material.026"/>
      <origin rpy="0.06589 -0.00000 -0.00000" xyz="0.00246 1.11602 -11.08254"/>
      <geometry>
        <mesh filename="${mesh_dir}/Texture.094.dae" scale="1.00000 1.00000 1.00000"/>
      </geometry>
    </visual>
    <visual name="i01.torso.full.008">
      <material name="Material.026"/>
      <origin rpy="0.06589 -0.00000 -0.00000" xyz="0.00246 1.11602 -11.08254"/>
      <geometry>
        <mesh filename="${mesh_dir}/Texture.095.dae" scale="1.00000 1.00000 1.00000"/>
      </geometry>
    </visual>
    <visual name="i01.torso.full.009">
      <material name="Material.026"/>
      <origin rpy="0.06589 -0.00000 -0.00000" xyz="0.00246 1.11602 -11.08254"/>
      <geometry>
        <mesh filename="${mesh_dir}/Texture.096.dae" scale="1.00000 1.00000 1.00000"/>
      </geometry>
    </visual>
    <visual name="i01.torso.full.010">
      <material name="Material.026"/>
      <origin rpy="0.06589 -0.00000 -0.00000" xyz="0.00246 1.11602 -11.08254"/>
      <geometry>
        <mesh filename="${mesh_dir}/Texture.097.dae" scale="1.00000 1.00000 1.00000"/>
      </geometry>
    </visual>
    <visual name="i01.torso.full.011">
      <material name="Material.026"/>
      <origin rpy="0.06589 -0.00000 -0.00000" xyz="0.00246 1.11602 -11.08254"/>
      <geometry>
        <mesh filename="${mesh_dir}/Texture.098.dae" scale="1.00000 1.00000 1.00000"/>
      </geometry>
    </visual>
    <visual name="i01.torso.full.012">
      <material name="Material.026"/>
      <origin rpy="0.06589 -0.00000 -0.00000" xyz="0.00246 1.11602 -11.08254"/>
      <geometry>
        <mesh filename="${mesh_dir}/Texture.099.dae" scale="1.00000 1.00000 1.00000"/>
      </geometry>
    </visual>
    <visual name="i01.torso.full.013">
      <material name="Material.026"/>
      <origin rpy="0.06589 -0.00000 -0.00000" xyz="0.00246 1.11602 -11.08254"/>
      <geometry>
        <mesh filename="${mesh_dir}/Texture.100.dae" scale="1.00000 1.00000 1.00000"/>
      </geometry>
    </visual>
    <visual name="i01.torso.full.014">
      <material name="Material.026"/>
      <origin rpy="0.06589 -0.00000 -0.00000" xyz="0.00246 1.11602 -11.08254"/>
      <geometry>
        <mesh filename="${mesh_dir}/Texture.101.dae" scale="1.00000 1.00000 1.00000"/>
      </geometry>
    </visual>
    <visual name="i01.torso.full.015">
      <material name="Material.026"/>
      <origin rpy="0.06589 -0.00000 -0.00000" xyz="0.00246 1.11602 -11.08254"/>
      <geometry>
        <mesh filename="${mesh_dir}/Texture.102.dae" scale="1.00000 1.00000 1.00000"/>
      </geometry>
    </visual>
    <visual name="i01.torso.full.016">
      <material name="Material.026"/>
      <origin rpy="0.06589 -0.00000 -0.00000" xyz="0.00246 1.11602 -11.08254"/>
      <geometry>
        <mesh filename="${mesh_dir}/Texture.103.dae" scale="1.00000 1.00000 1.00000"/>
      </geometry>
    </visual>
    <visual name="i01.torso.full.017">
      <material name="Material.026"/>
      <origin rpy="0.06589 -0.00000 -0.00000" xyz="0.00246 1.11602 -11.08254"/>
      <geometry>
        <mesh filename="${mesh_dir}/Texture.104.dae" scale="1.00000 1.00000 1.00000"/>
      </geometry>
    </visual>
    <visual name="i01.torso.full.018">
      <material name="Material.026"/>
      <origin rpy="0.06589 -0.00000 -0.00000" xyz="0.00246 1.11602 -11.08254"/>
      <geometry>
        <mesh filename="${mesh_dir}/Texture.105.dae" scale="1.00000 1.00000 1.00000"/>
      </geometry>
    </visual>
    <visual name="i01.torso.full.019">
      <material name="Material.026"/>
      <origin rpy="0.06589 -0.00000 -0.00000" xyz="0.00246 1.11602 -11.08254"/>
      <geometry>
        <mesh filename="${mesh_dir}/Texture.106.dae" scale="1.00000 1.00000 1.00000"/>
      </geometry>
    </visual>
    <visual name="i01.torso.full.020">
      <material name="Material.026"/>
      <origin rpy="0.06589 -0.00000 -0.00000" xyz="0.00246 1.11602 -11.08254"/>
      <geometry>
        <mesh filename="${mesh_dir}/Texture.107.dae" scale="1.00000 1.00000 1.00000"/>
      </geometry>
    </visual>
    <visual name="i01.torso.full.021">
      <material name="Material.026"/>
      <origin rpy="0.06589 -0.00000 -0.00000" xyz="0.00246 1.11602 -11.08254"/>
      <geometry>
        <mesh filename="${mesh_dir}/Texture.108.dae" scale="1.00000 1.00000 1.00000"/>
      </geometry>
    </visual>
    <visual name="i01.torso.full.022">
      <material name="Material.026"/>
      <origin rpy="0.06589 -0.00000 -0.00000" xyz="0.00246 1.11602 -11.08254"/>
      <geometry>
        <mesh filename="${mesh_dir}/Texture.109.dae" scale="1.00000 1.00000 1.00000"/>
      </geometry>
    </visual>
    <visual name="i01.torso.full.023">
      <material name="Material.026"/>
      <origin rpy="0.06589 -0.00000 -0.00000" xyz="0.00246 1.11602 -11.08254"/>
      <geometry>
        <mesh filename="${mesh_dir}/Texture.110.dae" scale="1.00000 1.00000 1.00000"/>
      </geometry>
    </visual>
    <visual name="i01.torso.full.024">
      <material name="Material.026"/>
      <origin rpy="0.06589 -0.00000 -0.00000" xyz="0.00246 1.11602 -11.08254"/>
      <geometry>
        <mesh filename="${mesh_dir}/Texture.111.dae" scale="1.00000 1.00000 1.00000"/>
      </geometry>
    </visual>
    <visual name="i01.torso.full.025">
      <material name="Material.026"/>
      <origin rpy="0.06589 -0.00000 -0.00000" xyz="0.00246 1.11602 -11.08254"/>
      <geometry>
        <mesh filename="${mesh_dir}/Texture.112.dae" scale="1.00000 1.00000 1.00000"/>
      </geometry>
    </visual>
    <visual name="i01.torso.full.026">
      <material name="Material.026"/>
      <origin rpy="0.06589 -0.00000 -0.00000" xyz="0.00246 1.11602 -11.08254"/>
      <geometry>
        <mesh filename="${mesh_dir}/Texture.113.dae" scale="1.00000 1.00000 1.00000"/>
      </geometry>
    </visual>
    <visual name="i01.torso.full.027">
      <material name="Material.026"/>
      <origin rpy="0.06589 -0.00000 -0.00000" xyz="0.00246 1.11602 -11.08254"/>
      <geometry>
        <mesh filename="${mesh_dir}/Texture.114.dae" scale="1.00000 1.00000 1.00000"/>
      </geometry>
    </visual>
    <visual name="i01.torso.full.028">
      <material name="Material.026"/>
      <origin rpy="0.06589 -0.00000 -0.00000" xyz="0.00246 1.11602 -11.08254"/>
      <geometry>
        <mesh filename="${mesh_dir}/Texture.115.dae" scale="1.00000 1.00000 1.00000"/>
      </geometry>
    </visual>
    <visual name="i01.torso.full.029">
      <material name="Material.026"/>
      <origin rpy="0.06589 -0.00000 -0.00000" xyz="0.00246 1.11602 -11.08254"/>
      <geometry>
        <mesh filename="${mesh_dir}/Texture.116.dae" scale="1.00000 1.00000 1.00000"/>
      </geometry>
    </visual>
    <visual name="i01.torso.full.030">
      <material name="Material.026"/>
      <origin rpy="0.06589 -0.00000 -0.00000" xyz="0.00246 1.11602 -11.08254"/>
      <geometry>
        <mesh filename="${mesh_dir}/Texture.117.dae" scale="1.00000 1.00000 1.00000"/>
      </geometry>
    </visual>
    <visual name="i01.torso.full.031">
      <material name="Material.026"/>
      <origin rpy="0.06589 -0.00000 -0.00000" xyz="0.00246 1.11602 -11.08254"/>
      <geometry>
        <mesh filename="${mesh_dir}/Texture.118.dae" scale="1.00000 1.00000 1.00000"/>
      </geometry>
    </visual>
    <visual name="i01.torso.full.032">
      <material name="Material.026"/>
      <origin rpy="0.06589 -0.00000 -0.00000" xyz="0.00246 1.11602 -11.08254"/>
      <geometry>
        <mesh filename="${mesh_dir}/Texture.119.dae" scale="1.00000 1.00000 1.00000"/>
      </geometry>
    </visual>
    <visual name="i01.torso.full.033">
      <material name="Material.026"/>
      <origin rpy="0.06589 -0.00000 -0.00000" xyz="0.00246 1.11602 -11.08254"/>
      <geometry>
        <mesh filename="${mesh_dir}/Texture.120.dae" scale="1.00000 1.00000 1.00000"/>
      </geometry>
    </visual>
    <visual name="i01.torso.full.034">
      <material name="Material.026"/>
      <origin rpy="0.06589 -0.00000 -0.00000" xyz="0.00246 1.11602 -11.08254"/>
      <geometry>
        <mesh filename="${mesh_dir}/Texture.121.dae" scale="1.00000 1.00000 1.00000"/>
      </geometry>
    </visual>
    <visual name="i01.torso.full.035">
      <material name="Material.026"/>
      <origin rpy="0.06589 -0.00000 -0.00000" xyz="0.00246 1.11602 -11.08254"/>
      <geometry>
        <mesh filename="${mesh_dir}/Texture.122.dae" scale="1.00000 1.00000 1.00000"/>
      </geometry>
    </visual>
    <visual name="i01.torso.full.036">
      <material name="Material.026"/>
      <origin rpy="0.06589 -0.00000 -0.00000" xyz="0.00246 1.11602 -11.08254"/>
      <geometry>
        <mesh filename="${mesh_dir}/Texture.123.dae" scale="1.00000 1.00000 1.00000"/>
      </geometry>
    </visual>
    <visual name="i01.torso.full.037">
      <material name="Material.026"/>
      <origin rpy="0.06589 -0.00000 -0.00000" xyz="0.00246 1.11602 -11.08254"/>
      <geometry>
        <mesh filename="${mesh_dir}/Texture.124.dae" scale="1.00000 1.00000 1.00000"/>
      </geometry>
    </visual>
    <visual name="i01.torso.full.038">
      <material name="Material.026"/>
      <origin rpy="0.06589 -0.00000 -0.00000" xyz="0.00246 1.11602 -11.08254"/>
      <geometry>
        <mesh filename="${mesh_dir}/Texture.125.dae" scale="1.00000 1.00000 1.00000"/>
      </geometry>
    </visual>
    <visual name="i01.torso.full.039">
      <material name="Material.026"/>
      <origin rpy="0.06589 -0.00000 -0.00000" xyz="0.00246 1.11602 -11.08254"/>
      <geometry>
        <mesh filename="${mesh_dir}/Texture.126.dae" scale="1.00000 1.00000 1.00000"/>
      </geometry>
    </visual>
    <visual name="i01.torso.full.040">
      <material name="Material.026"/>
      <origin rpy="0.06589 -0.00000 -0.00000" xyz="0.00246 1.11602 -11.08254"/>
      <geometry>
        <mesh filename="${mesh_dir}/Texture.127.dae" scale="1.00000 1.00000 1.00000"/>
      </geometry>
    </visual>
    <visual name="i01.torso.full.041">
      <material name="Material.026"/>
      <origin rpy="0.06589 -0.00000 -0.00000" xyz="0.00246 1.11602 -11.08254"/>
      <geometry>
        <mesh filename="${mesh_dir}/Texture.128.dae" scale="1.00000 1.00000 1.00000"/>
      </geometry>
    </visual>
    <visual name="i01.torso.full.042">
      <material name="Material.026"/>
      <origin rpy="0.06589 -0.00000 -0.00000" xyz="0.00246 1.11602 -11.08254"/>
      <geometry>
        <mesh filename="${mesh_dir}/Texture.129.dae" scale="1.00000 1.00000 1.00000"/>
      </geometry>
    </visual>
    <visual name="i01.torso.full.043">
      <material name="Material.026"/>
      <origin rpy="0.06589 -0.00000 -0.00000" xyz="0.00246 1.11602 -11.08254"/>
      <geometry>
        <mesh filename="${mesh_dir}/Texture.130.dae" scale="1.00000 1.00000 1.00000"/>
      </geometry>
    </visual>
    <visual name="i01.torso.full.044">
      <material name="Material.026"/>
      <origin rpy="0.06589 -0.00000 -0.00000" xyz="0.00246 1.11602 -11.08254"/>
      <geometry>
        <mesh filename="${mesh_dir}/Texture.131.dae" scale="1.00000 1.00000 1.00000"/>
      </geometry>
    </visual>
    <visual name="i01.torso.full.045">
      <material name="Material.026"/>
      <origin rpy="0.06589 -0.00000 -0.00000" xyz="0.00246 1.11602 -11.08254"/>
      <geometry>
        <mesh filename="${mesh_dir}/Texture.132.dae" scale="1.00000 1.00000 1.00000"/>
      </geometry>
    </visual>
    <visual name="i01.torso.full.046">
      <material name="Material.026"/>
      <origin rpy="0.06589 -0.00000 -0.00000" xyz="0.00246 1.11602 -11.08254"/>
      <geometry>
        <mesh filename="${mesh_dir}/Texture.133.dae" scale="1.00000 1.00000 1.00000"/>
      </geometry>
    </visual>
    <visual name="i01.torso.full.047">
      <material name="Material.026"/>
      <origin rpy="0.06589 -0.00000 -0.00000" xyz="0.00246 1.11602 -11.08254"/>
      <geometry>
        <mesh filename="${mesh_dir}/Texture.134.dae" scale="1.00000 1.00000 1.00000"/>
      </geometry>
    </visual>
    <visual name="i01.torso.full.048">
      <material name="Material.026"/>
      <origin rpy="0.06589 -0.00000 -0.00000" xyz="0.00246 1.11602 -11.08254"/>
      <geometry>
        <mesh filename="${mesh_dir}/Texture.135.dae" scale="1.00000 1.00000 1.00000"/>
      </geometry>
    </visual>
    <visual name="i01.torso.full.049">
      <material name="Material.026"/>
      <origin rpy="0.06589 -0.00000 -0.00000" xyz="0.00246 1.11602 -11.08254"/>
      <geometry>
        <mesh filename="${mesh_dir}/Texture.136.dae" scale="1.00000 1.00000 1.00000"/>
      </geometry>
    </visual>
    <visual name="i01.torso.full.050">
      <material name="Material.026"/>
      <origin rpy="0.06589 -0.00000 -0.00000" xyz="0.00246 1.11602 -11.08254"/>
      <geometry>
        <mesh filename="${mesh_dir}/Texture.137.dae" scale="1.00000 1.00000 1.00000"/>
      </geometry>
    </visual>
    <visual name="i01.torso.full.051">
      <material name="Material.026"/>
      <origin rpy="0.06589 -0.00000 -0.00000" xyz="0.00246 1.11602 -11.08254"/>
      <geometry>
        <mesh filename="${mesh_dir}/Texture.138.dae" scale="1.00000 1.00000 1.00000"/>
      </geometry>
    </visual>
    <visual name="i01.torso.full.052">
      <material name="Material.026"/>
      <origin rpy="0.06589 -0.00000 -0.00000" xyz="0.00246 1.11602 -11.08254"/>
      <geometry>
        <mesh filename="${mesh_dir}/Texture.139.dae" scale="1.00000 1.00000 1.00000"/>
      </geometry>
    </visual>
    <visual name="i01.torso.full.053">
      <material name="Material.026"/>
      <origin rpy="0.06589 -0.00000 -0.00000" xyz="0.00246 1.11602 -11.08254"/>
      <geometry>
        <mesh filename="${mesh_dir}/Texture.140.dae" scale="1.00000 1.00000 1.00000"/>
      </geometry>
    </visual>
    <visual name="i01.torso.full.054">
      <material name="Material.026"/>
      <origin rpy="0.06589 -0.00000 -0.00000" xyz="0.00246 1.11602 -11.08254"/>
      <geometry>
        <mesh filename="${mesh_dir}/Texture.141.dae" scale="1.00000 1.00000 1.00000"/>
      </geometry>
    </visual>
    <visual name="i01.torso.full.055">
      <material name="Material.026"/>
      <origin rpy="0.06589 -0.00000 -0.00000" xyz="0.00246 1.11602 -11.08254"/>
      <geometry>
        <mesh filename="${mesh_dir}/Texture.142.dae" scale="1.00000 1.00000 1.00000"/>
      </geometry>
    </visual>
    <visual name="i01.torso.full.056">
      <material name="Material.026"/>
      <origin rpy="0.06589 -0.00000 -0.00000" xyz="0.00246 1.11602 -11.08254"/>
      <geometry>
        <mesh filename="${mesh_dir}/Texture.143.dae" scale="1.00000 1.00000 1.00000"/>
      </geometry>
    </visual>
    <visual name="i01.torso.full.057">
      <material name="Material.026"/>
      <origin rpy="0.06589 -0.00000 -0.00000" xyz="0.00246 1.11602 -11.08254"/>
      <geometry>
        <mesh filename="${mesh_dir}/Texture.144.dae" scale="1.00000 1.00000 1.00000"/>
      </geometry>
    </visual>
    <visual name="i01.torso.full.058">
      <material name="Material.026"/>
      <origin rpy="0.06589 -0.00000 -0.00000" xyz="0.00246 1.11602 -11.08254"/>
      <geometry>
        <mesh filename="${mesh_dir}/Texture.145.dae" scale="1.00000 1.00000 1.00000"/>
      </geometry>
    </visual>
    <visual name="i01.torso.full.059">
      <material name="Material.026"/>
      <origin rpy="0.06589 -0.00000 -0.00000" xyz="0.00246 1.11602 -11.08254"/>
      <geometry>
        <mesh filename="${mesh_dir}/Texture.146.dae" scale="1.00000 1.00000 1.00000"/>
      </geometry>
    </visual>
    <visual name="i01.torso.full.060">
      <material name="Material.026"/>
      <origin rpy="0.06589 -0.00000 -0.00000" xyz="0.00246 1.11602 -11.08254"/>
      <geometry>
        <mesh filename="${mesh_dir}/Texture.147.dae" scale="1.00000 1.00000 1.00000"/>
      </geometry>
    </visual>
    <visual name="i01.torso.full.061">
      <material name="Material.026"/>
      <origin rpy="0.06589 -0.00000 -0.00000" xyz="0.00246 1.11602 -11.08254"/>
      <geometry>
        <mesh filename="${mesh_dir}/Texture.148.dae" scale="1.00000 1.00000 1.00000"/>
      </geometry>
    </visual>
    <visual name="i01.torso.full.062">
      <material name="Material.026"/>
      <origin rpy="0.06589 -0.00000 -0.00000" xyz="0.00246 1.11602 -11.08254"/>
      <geometry>
        <mesh filename="${mesh_dir}/Texture.149.dae" scale="1.00000 1.00000 1.00000"/>
      </geometry>
    </visual>
    <visual name="i01.torso.full.063">
      <material name="Material.026"/>
      <origin rpy="0.06589 -0.00000 -0.00000" xyz="0.00246 1.11602 -11.08254"/>
      <geometry>
        <mesh filename="${mesh_dir}/Texture.150.dae" scale="1.00000 1.00000 1.00000"/>
      </geometry>
    </visual>
    <visual name="i01.torso.full.064">
      <material name="Material.026"/>
      <origin rpy="0.06589 -0.00000 -0.00000" xyz="0.00246 1.11602 -11.08254"/>
      <geometry>
        <mesh filename="${mesh_dir}/Texture.151.dae" scale="1.00000 1.00000 1.00000"/>
      </geometry>
    </visual>
    <visual name="i01.torso.full.065">
      <material name="Material.026"/>
      <origin rpy="0.06589 -0.00000 -0.00000" xyz="0.00246 1.11602 -11.08254"/>
      <geometry>
        <mesh filename="${mesh_dir}/Texture.152.dae" scale="1.00000 1.00000 1.00000"/>
      </geometry>
    </visual>
    <visual name="i01.torso.full.066">
      <material name="Material.026"/>
      <origin rpy="0.06589 -0.00000 -0.00000" xyz="0.00246 1.11602 -11.08254"/>
      <geometry>
        <mesh filename="${mesh_dir}/Texture.153.dae" scale="1.00000 1.00000 1.00000"/>
      </geometry>
    </visual>
    <visual name="i01.torso.full.067">
      <material name="Material.026"/>
      <origin rpy="0.06589 -0.00000 -0.00000" xyz="0.00246 1.11602 -11.08254"/>
      <geometry>
        <mesh filename="${mesh_dir}/Texture.154.dae" scale="1.00000 1.00000 1.00000"/>
      </geometry>
    </visual>
    <visual name="i01.torso.full.068">
      <material name="Material.026"/>
      <origin rpy="0.06589 -0.00000 -0.00000" xyz="0.00246 1.11602 -11.08254"/>
      <geometry>
        <mesh filename="${mesh_dir}/Texture.155.dae" scale="1.00000 1.00000 1.00000"/>
      </geometry>
    </visual>
    <visual name="i01.torso.full.069">
      <material name="Material.026"/>
      <origin rpy="0.06589 -0.00000 -0.00000" xyz="0.00246 1.11602 -11.08254"/>
      <geometry>
        <mesh filename="${mesh_dir}/Texture.156.dae" scale="1.00000 1.00000 1.00000"/>
      </geometry>
    </visual>
    <visual name="i01.torso.full.070">
      <material name="Material.026"/>
      <origin rpy="0.06589 -0.00000 -0.00000" xyz="0.00246 1.11602 -11.08254"/>
      <geometry>
        <mesh filename="${mesh_dir}/Texture.157.dae" scale="1.00000 1.00000 1.00000"/>
      </geometry>
    </visual>
    <visual name="i01.torso.full.071">
      <material name="Material.026"/>
      <origin rpy="0.06589 -0.00000 -0.00000" xyz="0.00246 1.11602 -11.08254"/>
      <geometry>
        <mesh filename="${mesh_dir}/Texture.158.dae" scale="1.00000 1.00000 1.00000"/>
      </geometry>
    </visual>
    <visual name="i01.torso.full.072">
      <material name="Material.026"/>
      <origin rpy="0.06589 -0.00000 -0.00000" xyz="0.00246 1.11602 -11.08254"/>
      <geometry>
        <mesh filename="${mesh_dir}/Texture.159.dae" scale="1.00000 1.00000 1.00000"/>
      </geometry>
    </visual>
    <visual name="i01.torso.full.073">
      <material name="Material.026"/>
      <origin rpy="0.06589 -0.00000 -0.00000" xyz="0.00246 1.11602 -11.08254"/>
      <geometry>
        <mesh filename="${mesh_dir}/Texture.160.dae" scale="1.00000 1.00000 1.00000"/>
      </geometry>
    </visual>
    <visual name="i01.torso.full.074">
      <material name="Material.026"/>
      <origin rpy="0.06589 -0.00000 -0.00000" xyz="0.00246 1.11602 -11.08254"/>
      <geometry>
        <mesh filename="${mesh_dir}/Texture.161.dae" scale="1.00000 1.00000 1.00000"/>
      </geometry>
    </visual>
    <visual name="i01.torso.full.075">
      <material name="Material.026"/>
      <origin rpy="0.06589 -0.00000 -0.00000" xyz="0.00246 1.11602 -11.08254"/>
      <geometry>
        <mesh filename="${mesh_dir}/Texture.162.dae" scale="1.00000 1.00000 1.00000"/>
      </geometry>
    </visual>
    <visual name="i01.torso.full.076">
      <material name="Material.026"/>
      <origin rpy="0.06589 -0.00000 -0.00000" xyz="0.00246 1.11602 -11.08254"/>
      <geometry>
        <mesh filename="${mesh_dir}/Texture.163.dae" scale="1.00000 1.00000 1.00000"/>
      </geometry>
    </visual>
    <visual name="i01.torso.full.077">
      <material name="Material.026"/>
      <origin rpy="0.06589 -0.00000 -0.00000" xyz="0.00246 1.11602 -11.08254"/>
      <geometry>
        <mesh filename="${mesh_dir}/Texture.164.dae" scale="1.00000 1.00000 1.00000"/>
      </geometry>
    </visual>
    <visual name="i01.torso.full.078">
      <material name="Material.026"/>
      <origin rpy="0.06589 -0.00000 -0.00000" xyz="0.00246 1.11602 -11.08254"/>
      <geometry>
        <mesh filename="${mesh_dir}/Texture.165.dae" scale="1.00000 1.00000 1.00000"/>
      </geometry>
    </visual>
    <visual name="i01.torso.full.079">
      <material name="Material.026"/>
      <origin rpy="0.06589 -0.00000 -0.00000" xyz="0.00246 1.11602 -11.08254"/>
      <geometry>
        <mesh filename="${mesh_dir}/Texture.166.dae" scale="1.00000 1.00000 1.00000"/>
      </geometry>
    </visual>
    <!-- Minimal inertial so urdf2sdf includes this link in Gazebo -->
    <inertial>
      <mass value="0.001"/>
      <inertia ixx="1e-6" ixy="0" ixz="0" iyy="1e-6" iyz="0" izz="1e-6"/>
    </inertial>
  </link>
  <link name="right_wrist_z_link">
    <visual name="i01.rightHand.Wristlarge">
      <material name="Material.629"/>
      <origin rpy="0.41605 0.00000 0.00000" xyz="1.99358 4.36715 -7.14139"/>
      <geometry>
        <mesh filename="${mesh_dir}/Texture.065.dae" scale="1.00000 1.00000 1.00000"/>
      </geometry>
    </visual>
    <inertial><mass value="0.001"/><inertia ixx="1e-6" ixy="0" ixz="0" iyy="1e-6" iyz="0" izz="1e-6"/></inertial>
  </link>
  <link name="i01.rightHand.wrist.001_link">
    <visual name="i01.rightHand.Wristlarge.001">
      <material name="Material.629"/>
      <origin rpy="0.41605 -0.00000 -0.63517" xyz="4.19587 2.33260 -6.97630"/>
      <geometry>
        <mesh filename="${mesh_dir}/Texture.204.dae" scale="1.00000 1.00000 1.00000"/>
      </geometry>
    </visual>
    <inertial><mass value="0.001"/><inertia ixx="1e-6" ixy="0" ixz="0" iyy="1e-6" iyz="0" izz="1e-6"/></inertial>
  </link>
  <link name="i01.rightHand.index_link">
    <visual name="i01.rightHand.indexPhal1">
      <material name="Material.632"/>
      <origin rpy="-1.15751 -0.61920 0.09256" xyz="5.01012 -5.59578 -2.39863"/>
      <geometry>
        <mesh filename="${mesh_dir}/Texture.044.dae" scale="1.00000 1.00000 1.00000"/>
      </geometry>
    </visual>
    <inertial><mass value="0.001"/><inertia ixx="1e-6" ixy="0" ixz="0" iyy="1e-6" iyz="0" izz="1e-6"/></inertial>
  </link>
  <link name="i01.rightHand.index2_link">
    <visual name="i01.rightHand.indexPhal2">
      <material name="Material.636"/>
      <origin rpy="-1.15751 -0.61920 0.09256" xyz="5.01271 -5.25474 -2.39178"/>
      <geometry>
        <mesh filename="${mesh_dir}/Texture.045.dae" scale="1.00000 1.00000 1.00000"/>
      </geometry>
    </visual>
    <inertial><mass value="0.001"/><inertia ixx="1e-6" ixy="0" ixz="0" iyy="1e-6" iyz="0" izz="1e-6"/></inertial>
  </link>
  <link name="i01.rightHand.index3_link">
    <visual name="i01.rightHand.indexPhal3">
      <material name="Material.640"/>
      <origin rpy="-1.15751 -0.61920 0.09256" xyz="5.01374 -5.02777 -2.38746"/>
      <geometry>
        <mesh filename="${mesh_dir}/Texture.046.dae" scale="1.00000 1.00000 1.00000"/>
      </geometry>
    </visual>
    <inertial><mass value="0.001"/><inertia ixx="1e-6" ixy="0" ixz="0" iyy="1e-6" iyz="0" izz="1e-6"/></inertial>
  </link>
  <link name="i01.rightHand.majeure_link">
    <visual name="i01.rightHand.majeurePhal1">
      <material name="Material.633"/>
      <origin rpy="-1.15751 -0.61920 -0.00000" xyz="4.21669 -5.99551 -2.39976"/>
      <geometry>
        <mesh filename="${mesh_dir}/Texture.048.dae" scale="1.00000 1.00000 1.00000"/>
      </geometry>
    </visual>
    <inertial><mass value="0.001"/><inertia ixx="1e-6" ixy="0" ixz="0" iyy="1e-6" iyz="0" izz="1e-6"/></inertial>
  </link>
  <link name="i01.rightHand.majeure2_link">
    <visual name="i01.rightHand.majeurePhal2">
      <material name="Material.637"/>
      <origin rpy="-1.15751 -0.61920 -0.00000" xyz="4.21941 -5.63616 -2.39254"/>
      <geometry>
        <mesh filename="${mesh_dir}/Texture.049.dae" scale="1.00000 1.00000 1.00000"/>
      </geometry>
    </visual>
    <inertial><mass value="0.001"/><inertia ixx="1e-6" ixy="0" ixz="0" iyy="1e-6" iyz="0" izz="1e-6"/></inertial>
  </link>
  <link name="i01.rightHand.majeure3_link">
    <visual name="i01.rightHand.majeurePhal3">
      <material name="Material.641"/>
      <origin rpy="-1.15751 -0.61920 0.00000" xyz="4.22050 -5.39701 -2.38798"/>
      <geometry>
        <mesh filename="${mesh_dir}/Texture.050.dae" scale="1.00000 1.00000 1.00000"/>
      </geometry>
    </visual>
    <inertial><mass value="0.001"/><inertia ixx="1e-6" ixy="0" ixz="0" iyy="1e-6" iyz="0" izz="1e-6"/></inertial>
  </link>
  <link name="i01.rightHand.pinky0_link">
    <visual name="i01.rightHand.WristSmall2">
      <material name="Material.630"/>
      <origin rpy="-1.15751 -0.61920 0.68804" xyz="7.22704 -2.64375 -2.38651"/>
      <geometry>
        <mesh filename="${mesh_dir}/Texture.067.dae" scale="1.00000 1.00000 1.00000"/>
      </geometry>
    </visual>
    <inertial><mass value="0.001"/><inertia ixx="1e-6" ixy="0" ixz="0" iyy="1e-6" iyz="0" izz="1e-6"/></inertial>
  </link>
  <link name="i01.rightHand.pinky_link">
    <visual name="i01.rightHand.pinkyPhal1">
      <material name="Material.635"/>
      <origin rpy="-1.15751 -0.61920 -0.25722" xyz="2.00181 -6.93660 -2.37926"/>
      <geometry>
        <mesh filename="${mesh_dir}/Texture.053.dae" scale="1.00000 1.00000 1.00000"/>
      </geometry>
    </visual>
    <inertial><mass value="0.001"/><inertia ixx="1e-6" ixy="0" ixz="0" iyy="1e-6" iyz="0" izz="1e-6"/></inertial>
  </link>
  <link name="i01.head.neck.001_link">
    <inertial><mass value="0.001"/><inertia ixx="1e-6" ixy="0" ixz="0" iyy="1e-6" iyz="0" izz="1e-6"/></inertial>
  </link>
  <link name="i01.rightHand.pinky2_link">
    <visual name="i01.rightHand.pinkyPhal2">
      <material name="Material.639"/>
      <origin rpy="-1.15751 -0.61921 -0.25722" xyz="2.00407 -6.63864 -2.37327"/>
      <geometry>
        <mesh filename="${mesh_dir}/Texture.054.dae" scale="1.00000 1.00000 1.00000"/>
      </geometry>
    </visual>
    <inertial><mass value="0.001"/><inertia ixx="1e-6" ixy="0" ixz="0" iyy="1e-6" iyz="0" izz="1e-6"/></inertial>
  </link>
  <link name="i01.rightHand.pinky3_link">
    <visual name="i01.rightHand.pinkyPhal3">
      <material name="Material.643"/>
      <origin rpy="-1.15751 -0.61921 -0.25722" xyz="2.00497 -6.44034 -2.36949"/>
      <geometry>
        <mesh filename="${mesh_dir}/Texture.055.dae" scale="1.00000 1.00000 1.00000"/>
      </geometry>
    </visual>
    <inertial><mass value="0.001"/><inertia ixx="1e-6" ixy="0" ixz="0" iyy="1e-6" iyz="0" izz="1e-6"/></inertial>
  </link>
  <link name="i01.rightHand.ringfinger0_link">
    <visual name="i01.rightHand.WristSmall">
      <material name="Material.631"/>
      <origin rpy="-1.15751 -0.61920 0.68804" xyz="7.22704 -2.35455 -2.38651"/>
      <geometry>
        <mesh filename="${mesh_dir}/Texture.066.dae" scale="1.00000 1.00000 1.00000"/>
      </geometry>
    </visual>
    <inertial><mass value="0.001"/><inertia ixx="1e-6" ixy="0" ixz="0" iyy="1e-6" iyz="0" izz="1e-6"/></inertial>
  </link>
  <link name="i01.rightHand.ringFinger_link">
    <visual name="i01.rightHand.ringFingerPhal1">
      <material name="Material.634"/>
      <origin rpy="-1.15751 -0.61920 -0.08681" xyz="3.38539 -6.39614 -2.39316"/>
      <geometry>
        <mesh filename="${mesh_dir}/Texture.058.dae" scale="1.00000 1.00000 1.00000"/>
      </geometry>
    </visual>
    <inertial><mass value="0.001"/><inertia ixx="1e-6" ixy="0" ixz="0" iyy="1e-6" iyz="0" izz="1e-6"/></inertial>
  </link>
  <link name="i01.rightHand.ringfinger2_link">
    <visual name="i01.rightHand.ringFingerPhal2">
      <material name="Material.638"/>
      <origin rpy="-1.15751 -0.61920 -0.08681" xyz="3.38797 -6.05509 -2.38631"/>
      <geometry>
        <mesh filename="${mesh_dir}/Texture.059.dae" scale="1.00000 1.00000 1.00000"/>
      </geometry>
    </visual>
    <inertial><mass value="0.001"/><inertia ixx="1e-6" ixy="0" ixz="0" iyy="1e-6" iyz="0" izz="1e-6"/></inertial>
  </link>
  <link name="i01.rightHand.ringfinger3_link">
    <visual name="i01.rightHand.ringFingerPhal3">
      <material name="Material.642"/>
      <origin rpy="-1.15751 -0.61920 -0.08681" xyz="3.38900 -5.82812 -2.38199"/>
      <geometry>
        <mesh filename="${mesh_dir}/Texture.060.dae" scale="1.00000 1.00000 1.00000"/>
      </geometry>
    </visual>
    <inertial><mass value="0.001"/><inertia ixx="1e-6" ixy="0" ixz="0" iyy="1e-6" iyz="0" izz="1e-6"/></inertial>
  </link>
  <link name="i01.rightHand.thumb1_link">
    <visual name="i01.rightHand.ThumbBase">
      <material name="Material.628"/>
      <origin rpy="2.05362 0.62375 -0.06004" xyz="5.06759 5.98847 2.72987"/>
      <geometry>
        <mesh filename="${mesh_dir}/Texture.063.dae" scale="1.00000 1.00000 1.00000"/>
      </geometry>
    </visual>
    <inertial><mass value="0.001"/><inertia ixx="1e-6" ixy="0" ixz="0" iyy="1e-6" iyz="0" izz="1e-6"/></inertial>
  </link>
  <link name="i01.rightHand.thumb_link">
    <visual name="i01.rightHand.ThumbMid">
      <material name="Material.627"/>
      <origin rpy="1.70891 0.82776 -1.11670" xyz="8.37077 0.01373 0.04665"/>
      <geometry>
        <mesh filename="${mesh_dir}/Texture.061.dae" scale="1.00000 1.00000 1.00000"/>
      </geometry>
    </visual>
    <inertial><mass value="0.001"/><inertia ixx="1e-6" ixy="0" ixz="0" iyy="1e-6" iyz="0" izz="1e-6"/></inertial>
  </link>
  <link name="i01.rightHand.thumb3_link">
    <visual name="i01.rightHand.ThumbTip">
      <material name="Material.626"/>
      <origin rpy="1.70890 0.82776 -1.11671" xyz="8.38306 -0.31675 0.03958"/>
      <geometry>
        <mesh filename="${mesh_dir}/Texture.062.dae" scale="1.00000 1.00000 1.00000"/>
      </geometry>
    </visual>
    <inertial><mass value="0.001"/><inertia ixx="1e-6" ixy="0" ixz="0" iyy="1e-6" iyz="0" izz="1e-6"/></inertial>
  </link>
  <link name="neck_link">
    <visual name="i01.head.nekHinge">
      <material name="Material.047"/>
      <origin rpy="0.00000 0.00000 0.00000" xyz="-0.00144 -0.19608 -15.39810"/>
      <geometry>
        <mesh filename="${mesh_dir}/Texture.015.dae" scale="1.00000 1.00000 1.00000"/>
      </geometry>
    </visual>
    <visual name="i01.head.nekHinge.001">
      <material name="Material.047"/>
      <origin rpy="0.00000 0.00000 0.00000" xyz="-0.00144 -0.19608 -15.39810"/>
      <geometry>
        <mesh filename="${mesh_dir}/Texture.083.dae" scale="1.00000 1.00000 1.00000"/>
      </geometry>
    </visual>
    <visual name="i01.head.nekHinge.002">
      <material name="Material.047"/>
      <origin rpy="0.00000 0.00000 0.00000" xyz="-0.00144 -0.19608 -15.39810"/>
      <geometry>
        <mesh filename="${mesh_dir}/Texture.084.dae" scale="1.00000 1.00000 1.00000"/>
      </geometry>
    </visual>
    <visual name="i01.head.nekHinge.003">
      <material name="Material.047"/>
      <origin rpy="0.00000 0.00000 0.00000" xyz="-0.00144 -0.19608 -15.39810"/>
      <geometry>
        <mesh filename="${mesh_dir}/Texture.085.dae" scale="1.00000 1.00000 1.00000"/>
      </geometry>
    </visual>
    <inertial><mass value="0.001"/><inertia ixx="1e-6" ixy="0" ixz="0" iyy="1e-6" iyz="0" izz="1e-6"/></inertial>
  </link>
  <link name="i01.head.rothead_link">
    <visual name="i01.head.full">
      <material name="Material.044"/>
      <origin rpy="0.00000 -0.00000 -1.57080" xyz="-0.21111 0.00389 -15.64721"/>
      <geometry>
        <mesh filename="${mesh_dir}/Texture.013.dae" scale="1.00000 1.00000 1.00000"/>
      </geometry>
    </visual>
    <visual name="i01.head.full.001">
      <material name="Material.044"/>
      <origin rpy="0.00000 -0.00000 -1.57080" xyz="-0.21111 0.00389 -15.64721"/>
      <geometry>
        <mesh filename="${mesh_dir}/Texture.068.dae" scale="1.00000 1.00000 1.00000"/>
      </geometry>
    </visual>
    <visual name="i01.head.full.002">
      <material name="Material.044"/>
      <origin rpy="0.00000 -0.00000 -1.57080" xyz="-0.21111 0.00389 -15.64721"/>
      <geometry>
        <mesh filename="${mesh_dir}/Texture.069.dae" scale="1.00000 1.00000 1.00000"/>
      </geometry>
    </visual>
    <visual name="i01.head.full.003">
      <material name="Material.044"/>
      <origin rpy="0.00000 -0.00000 -1.57080" xyz="-0.21111 0.00389 -15.64721"/>
      <geometry>
        <mesh filename="${mesh_dir}/Texture.070.dae" scale="1.00000 1.00000 1.00000"/>
      </geometry>
    </visual>
    <visual name="i01.head.full.004">
      <material name="Material.044"/>
      <origin rpy="0.00000 -0.00000 -1.57080" xyz="-0.21111 0.00389 -15.64721"/>
      <geometry>
        <mesh filename="${mesh_dir}/Texture.071.dae" scale="1.00000 1.00000 1.00000"/>
      </geometry>
    </visual>
    <visual name="i01.head.full.005">
      <material name="Material.044"/>
      <origin rpy="0.00000 -0.00000 -1.57080" xyz="-0.21111 0.00389 -15.64721"/>
      <geometry>
        <mesh filename="${mesh_dir}/Texture.072.dae" scale="1.00000 1.00000 1.00000"/>
      </geometry>
    </visual>
    <visual name="i01.head.full.006">
      <material name="Material.044"/>
      <origin rpy="0.00000 -0.00000 -1.57080" xyz="-0.21111 0.00389 -15.64721"/>
      <geometry>
        <mesh filename="${mesh_dir}/Texture.073.dae" scale="1.00000 1.00000 1.00000"/>
      </geometry>
    </visual>
    <visual name="i01.head.full.007">
      <material name="Material.044"/>
      <origin rpy="0.00000 -0.00000 -1.57080" xyz="-0.21111 0.00389 -15.64721"/>
      <geometry>
        <mesh filename="${mesh_dir}/Texture.074.dae" scale="1.00000 1.00000 1.00000"/>
      </geometry>
    </visual>
    <visual name="i01.head.full.008">
      <material name="Material.044"/>
      <origin rpy="0.00000 -0.00000 -1.57080" xyz="-0.21111 0.00389 -15.64721"/>
      <geometry>
        <mesh filename="${mesh_dir}/Texture.075.dae" scale="1.00000 1.00000 1.00000"/>
      </geometry>
    </visual>
    <visual name="i01.head.full.009">
      <material name="Material.044"/>
      <origin rpy="0.00000 -0.00000 -1.57080" xyz="-0.21111 0.00389 -15.64721"/>
      <geometry>
        <mesh filename="${mesh_dir}/Texture.076.dae" scale="1.00000 1.00000 1.00000"/>
      </geometry>
    </visual>
    <visual name="i01.head.full.010">
      <material name="Material.044"/>
      <origin rpy="0.00000 -0.00000 -1.57080" xyz="-0.21111 0.00389 -15.64721"/>
      <geometry>
        <mesh filename="${mesh_dir}/Texture.077.dae" scale="1.00000 1.00000 1.00000"/>
      </geometry>
    </visual>
    <visual name="i01.head.full.011">
      <material name="Material.044"/>
      <origin rpy="0.00000 -0.00000 -1.57080" xyz="-0.21111 0.00389 -15.64721"/>
      <geometry>
        <mesh filename="${mesh_dir}/Texture.078.dae" scale="1.00000 1.00000 1.00000"/>
      </geometry>
    </visual>
    <visual name="i01.head.full.012">
      <material name="Material.044"/>
      <origin rpy="0.00000 -0.00000 -1.57080" xyz="-0.21111 0.00389 -15.64721"/>
      <geometry>
        <mesh filename="${mesh_dir}/Texture.079.dae" scale="1.00000 1.00000 1.00000"/>
      </geometry>
    </visual>
    <visual name="i01.head.full.013">
      <material name="Material.044"/>
      <origin rpy="0.00000 -0.00000 -1.57080" xyz="-0.21111 0.00389 -15.64721"/>
      <geometry>
        <mesh filename="${mesh_dir}/Texture.080.dae" scale="1.00000 1.00000 1.00000"/>
      </geometry>
    </visual>
    <visual name="i01.head.full.014">
      <material name="Material.044"/>
      <origin rpy="0.00000 -0.00000 -1.57080" xyz="-0.21111 0.00389 -15.64721"/>
      <geometry>
        <mesh filename="${mesh_dir}/Texture.081.dae" scale="1.00000 1.00000 1.00000"/>
      </geometry>
    </visual>
    <visual name="i01.head.full.015">
      <material name="Material.044"/>
      <origin rpy="0.00000 -0.00000 -1.57080" xyz="-0.21111 0.00389 -15.64721"/>
      <geometry>
        <mesh filename="${mesh_dir}/Texture.082.dae" scale="1.00000 1.00000 1.00000"/>
      </geometry>
    </visual>
    <inertial><mass value="0.001"/><inertia ixx="1e-6" ixy="0" ixz="0" iyy="1e-6" iyz="0" izz="1e-6"/></inertial>
  </link>
  <link name="i01.head.eyeLeft.001_link">
    <inertial><mass value="0.001"/><inertia ixx="1e-6" ixy="0" ixz="0" iyy="1e-6" iyz="0" izz="1e-6"/></inertial>
  </link>
  <link name="i01.head.eyeLeft_link">
    <visual name="i01.head.eyeLeft.full">
      <material name="Material.035"/>
      <origin rpy="-0.00000 -0.00000 -0.00000" xyz="-0.29587 0.88079 -16.02298"/>
      <geometry>
        <mesh filename="${mesh_dir}/Texture.011.dae" scale="1.00000 1.00000 1.00000"/>
      </geometry>
    </visual>
    <inertial><mass value="0.001"/><inertia ixx="1e-6" ixy="0" ixz="0" iyy="1e-6" iyz="0" izz="1e-6"/></inertial>
  </link>
  <material name="Material.007">
    <color rgba="0.46275 0.28235 0.10588 1.00000"/>
  </material>
  <material name="Material.008">
    <color rgba="0.00000 0.00000 0.00000 1.00000"/>
  </material>
  <material name="Material.012">
    <color rgba="0.00000 0.00000 0.00000 1.00000"/>
  </material>
  <material name="Material.016">
    <color rgba="0.01569 0.01569 0.02745 1.00000"/>
  </material>
  <material name="Material.022">
    <color rgba="1.00000 1.00000 1.00000 1.00000"/>
  </material>
  <material name="Material.026">
    <color rgba="0.00000 0.00000 0.00000 1.00000"/>
  </material>
  <material name="Material.031">
    <color rgba="0.00000 0.00000 0.00000 1.00000"/>
  </material>
  <material name="Material.035">
    <color rgba="1.00000 1.00000 1.00000 1.00000"/>
  </material>
  <material name="Material.038">
    <color rgba="1.00000 1.00000 1.00000 1.00000"/>
  </material>
  <material name="Material.044">
    <color rgba="0.00000 0.00000 0.00000 1.00000"/>
  </material>
  <material name="Material.046">
    <color rgba="1.00000 1.00000 1.00000 1.00000"/>
  </material>
  <material name="Material.047">
    <color rgba="0.00000 0.00000 0.00000 1.00000"/>
  </material>
  <material name="Material.238">
    <color rgba="0.76078 0.75686 0.80000 1.00000"/>
  </material>
  <material name="Material.239">
    <color rgba="0.00000 0.00000 0.00000 1.00000"/>
  </material>
  <material name="Material.254">
    <color rgba="0.01569 0.01569 0.02745 1.00000"/>
  </material>
  <material name="Material.390">
    <color rgba="0.94510 0.96078 0.90980 1.00000"/>
  </material>
  <material name="Material.601">
    <color rgba="1.00000 1.00000 1.00000 1.00000"/>
  </material>
  <material name="Material.602">
    <color rgba="1.00000 1.00000 1.00000 1.00000"/>
  </material>
  <material name="Material.603">
    <color rgba="1.00000 1.00000 1.00000 1.00000"/>
  </material>
  <material name="Material.604">
    <color rgba="1.00000 1.00000 1.00000 1.00000"/>
  </material>
  <material name="Material.605">
    <color rgba="1.00000 1.00000 1.00000 1.00000"/>
  </material>
  <material name="Material.606">
    <color rgba="1.00000 1.00000 1.00000 1.00000"/>
  </material>
  <material name="Material.607">
    <color rgba="1.00000 1.00000 1.00000 1.00000"/>
  </material>
  <material name="Material.608">
    <color rgba="1.00000 1.00000 1.00000 1.00000"/>
  </material>
  <material name="Material.609">
    <color rgba="1.00000 1.00000 1.00000 1.00000"/>
  </material>
  <material name="Material.610">
    <color rgba="1.00000 1.00000 1.00000 1.00000"/>
  </material>
  <material name="Material.611">
    <color rgba="1.00000 1.00000 1.00000 1.00000"/>
  </material>
  <material name="Material.612">
    <color rgba="1.00000 1.00000 1.00000 1.00000"/>
  </material>
  <material name="Material.613">
    <color rgba="1.00000 1.00000 1.00000 1.00000"/>
  </material>
  <material name="Material.614">
    <color rgba="1.00000 1.00000 1.00000 1.00000"/>
  </material>
  <material name="Material.615">
    <color rgba="1.00000 1.00000 1.00000 1.00000"/>
  </material>
  <material name="Material.616">
    <color rgba="1.00000 1.00000 1.00000 1.00000"/>
  </material>
  <material name="Material.617">
    <color rgba="1.00000 1.00000 1.00000 1.00000"/>
  </material>
  <material name="Material.618">
    <color rgba="1.00000 1.00000 1.00000 1.00000"/>
  </material>
  <material name="Material.626">
    <color rgba="1.00000 1.00000 1.00000 1.00000"/>
  </material>
  <material name="Material.627">
    <color rgba="1.00000 1.00000 1.00000 1.00000"/>
  </material>
  <material name="Material.628">
    <color rgba="1.00000 1.00000 1.00000 1.00000"/>
  </material>
  <material name="Material.629">
    <color rgba="1.00000 1.00000 1.00000 1.00000"/>
  </material>
  <material name="Material.630">
    <color rgba="1.00000 1.00000 1.00000 1.00000"/>
  </material>
  <material name="Material.631">
    <color rgba="1.00000 1.00000 1.00000 1.00000"/>
  </material>
  <material name="Material.632">
    <color rgba="1.00000 1.00000 1.00000 1.00000"/>
  </material>
  <material name="Material.633">
    <color rgba="1.00000 1.00000 1.00000 1.00000"/>
  </material>
  <material name="Material.634">
    <color rgba="1.00000 1.00000 1.00000 1.00000"/>
  </material>
  <material name="Material.635">
    <color rgba="1.00000 1.00000 1.00000 1.00000"/>
  </material>
  <material name="Material.636">
    <color rgba="1.00000 1.00000 1.00000 1.00000"/>
  </material>
  <material name="Material.637">
    <color rgba="1.00000 1.00000 1.00000 1.00000"/>
  </material>
  <material name="Material.638">
    <color rgba="1.00000 1.00000 1.00000 1.00000"/>
  </material>
  <material name="Material.639">
    <color rgba="1.00000 1.00000 1.00000 1.00000"/>
  </material>
  <material name="Material.640">
    <color rgba="1.00000 1.00000 1.00000 1.00000"/>
  </material>
  <material name="Material.641">
    <color rgba="1.00000 1.00000 1.00000 1.00000"/>
  </material>
  <material name="Material.642">
    <color rgba="1.00000 1.00000 1.00000 1.00000"/>
  </material>
  <material name="Material.643">
    <color rgba="1.00000 1.00000 1.00000 1.00000"/>
  </material>
  <material name="[0131_Silver]">
    <color rgba="0.74902 0.74902 0.74902 1.00000"/>
  </material>
  <material name="[0131_Silver].001">
    <color rgba="0.74902 0.74902 0.74902 1.00000"/>
  </material>
</robot>
